Workbook

Sheet Statistics
A1: Section | B1: Publication Date | C1: Album | D1: Song Count
A2: 1990-1999 | B2: 1988 | C2: Spirit and Truth | D2: 11
B3: 1990 | C3: Show Your Glory | D3: 14
B4: 1992 | C4: The Power of Your Love | D4: 16
B5: 1993 | C5: Stone's Been Rolled Away | D5: 14
B6: 1994 | C6: People Just Like Us | D6: 14
B7: 1995 | C7: Friends in High Places | D7: 15
B8: 1996 | C8: God Is in the House | D8: 15
B9: 1997 | C9: All Things Are Possible | D9: 15
B10: 1998 | C10: Touching Heaven Changing Earth | D10: 15
B11: 1999 | C11: By Your Side | D11: 14 | E11: =SUM(D2:D11) -> 143
A12: 2000-2009 | B12: 2000 | C12: For This Cause | D12: 14
B13: 2001 | C13: You Are My World | D13: 13
B14: 2002 | C14: Blessed | D14: 14
B15: 2003 | C15: Hope | D15: 18
B16: 2004 | C16: For All You've Done | D16: 15
B17: 2005 | C17: God He Reigns | D17: 15
B18: 2006 | C18: Mighty to Save | D18: 14
B19: 2007 | C19: Saviour King | D19: 14
B20: 2008 | C20: This Is Our God | D20: 16
B21: 2009 | C21: Faith + Hope + Love | D21: 13 | E21: =SUM(D12:D21) -> 146
A22: 2010-2020 | B22: 2010 | C22: A Beautiful Exchange | D22: 13
B23: 2011 | C23: God Is Able | D23: 13
B24: 2012 | C24: Cornerstone | D24: 13
B25: 2013 | C25: Glorious Ruins | D25: 11
B26: 2014 | C26: No Other Name | D26: 11
B27: 2015 | C27: Open Heaven / River Wild | D27: 12
B28: 2016 | C28: Let There Be Light | D28: 12
B29: 2017 | C29: The Peace Project | D29: 12
B30: 2018 | C30: There Is More | D30: 12
B31: 2019 | C31: Awake | D31: 15
B32: 2020 | C32: Take Heart (Again) | D32: 12 | E32: =SUM(D22:D32) -> 136

Sheet Albums
A1: # | B1: Year | C1: Title | D1: Tracks | E1: In List? | F1: Band | G1: Type | H1: Category | I1: Exclude | J1: AlbumArt | K1: Notes
A2: 1 | B2: 1988 | C2: Spirit and Truth | D2: 11 | E2: =IF(COUNTIF(Songs!$C:$C,C2)>0,"","NO") | F2: Worship | G2: Studio | J2: Other
A3: 2 | B3: 1990 | C3: Show Your Glory | D3: 14 | E3: =IF(COUNTIF(Songs!$C:$C,C3)>0,"","NO") | F3: Worship | G3: Studio | J3: Other
A4: 3 | B4: 1992 | C4: The Power of Your Love | D4: 16 | E4: =IF(COUNTIF(Songs!$C:$C,C4)>0,"","NO") | F4: Worship | G4: Live | J4: Other
A5: 4 | B5: 1993 | C5: Stone's Been Rolled Away | D5: 14 | E5: =IF(COUNTIF(Songs!$C:$C,C5)>0,"","NO") | F5: Worship | G5: Live | J5: Other
A6: 5 | B6: 1994 | C6: People Just Like Us | D6: 14 | E6: =IF(COUNTIF(Songs!$C:$C,C6)>0,"","NO") | F6: Worship | G6: Live | J6: YES
A7: 6 | B7: 1995 | C7: Friends in High Places | D7: 15 | E7: =IF(COUNTIF(Songs!$C:$C,C7)>0,"","NO") | F7: Worship | G7: Live | J7: YES
A8: 7 | B8: 1996 | C8: God Is in the House | D8: 15 | E8: =IF(COUNTIF(Songs!$C:$C,C8)>0,"","NO") | F8: Worship | G8: Live | J8: YES
A9: 8 | B9: 1996 | C9: Shout To The Lord | D9: 16 | E9: =IF(COUNTIF(Songs!$C:$C,C9)>0,"","NO") | F9: Worship | G9: Live | J9: YES
A10: 9 | B10: 1996 | C10: Simply Worship | D10: 12 | E10: =IF(COUNTIF(Songs!$C:$C,C10)>0,"","NO") | F10: Worship | G10: Live | J10: YES
A11: 10 | B11: 1997 | C11: All Things Are Possible | D11: 15 | E11: =IF(COUNTIF(Songs!$C:$C,C11)>0,"","NO") | F11: Worship | G11: Live | J11: YES
A12: 11 | B12: 1997 | C12: Simply Worship 2 | D12: 12 | E12: =IF(COUNTIF(Songs!$C:$C,C12)>0,"","NO") | F12: Worship | G12: Live | J12: YES
A13: 12 | B13: 1998 | C13: Shout to the Lord 2000 | D13: 16 | E13: =IF(COUNTIF(Songs!$C:$C,C13)>0,"","NO") | F13: Worship | G13: Live | J13: Other
... A17: 16 | B17: 1999 | C17: Everyday | D17: 10 | E17: =IF(COUNTIF(Songs!$C:$C,C17)>0,"","NO") | F17: United | G17: Live | J17: YES
A18: 17 | B18: 1999 | C18: The Secret Place | D18: 10 | E18: =IF(COUNTIF(Songs!$C:$C,C18)>0,"","NO") -> NO | F18: Worship | G18: Live | H18: Instrumental | I18: Exclude | J18: YES
A19: 18 | B19: 2000 | C19: Best Friend | D19: 10 | E19: =IF(COUNTIF(Songs!$C:$C,C19)>0,"","NO") | F19: United | G19: Live | J19: YES
A20: 19 | B20: 2000 | C20: For This Cause | D20: 14 | E20: =IF(COUNTIF(Songs!$C:$C,C20)>0,"","NO") | F20: Worship | G20: Live | J20: YES
A21: 20 | B21: 2000 | C21: Overwhelmed | D21: 12 | E21: =IF(COUNTIF(Songs!$C:$C,C21)>0,"","NO") | F21: Worship | G21: Live | J21: YES
A22: 21 | B22: 2001 | C22: Christmas | D22: 14 | E22: =IF(COUNTIF(Songs!$C:$C,C22)>0,"","NO") | F22: Worship | G22: Live | H22: Christmas | J22: YES
A23: 22 | B23: 2001 | C23: King of Majesty | D23: 11 | E23: =IF(COUNTIF(Songs!$C:$C,C23)>0,"","NO") | F23: United | G23: Live | J23: YES
A24: 23 | B24: 2001 | C24: You Are My World | D24: 13 | E24: =IF(COUNTIF(Songs!$C:$C,C24)>0,"","NO") | F24: Worship | G24: Live | J24: YES
A25: 24 | B25: 2002 | C25: Blessed | D25: 14 | E25: =IF(COUNTIF(Songs!$C:$C,C25)>0,"","NO") | F25: Worship | G25: Live | J25: YES
A26: 25 | B26: 2002 | C26: Extravagant Worship: The Songs Of Darlene Zschech | D26: 23 | E26: =IF(COUNTIF(Songs!$C:$C,C26)>0,"","NO") -> NO | F26: Worship | G26: Live | H26: Compilation | I26: Exclude | J26: YES
A27: 26 | B27: 2002 | C27: Extravagant Worship: The Songs Of Reuben Morgan | D27: 22 | E27: =IF(COUNTIF(Songs!$C:$C,C27)>0,"","NO") -> NO | F27: Worship | G27: Live | H27: Compilation | I27: Exclude | J27: YES
A28: 27 | B28: 2002 | C28: To the Ends of the Earth | D28: 14 | E28: =IF(COUNTIF(Songs!$C:$C,C28)>0,"","NO") | F28: United | G28: Live | J28: YES
A29: 28 | B29: 2003 | C29: Forever | D29: 10 | E29: =IF(COUNTIF(Songs!$C:$C,C29)>0,"","NO") -> NO | F29: Worship | G29: Live | H29: Instrumental | I29: Exclude | J29: YES
A30: 29 | B30: 2003 | C30: Hope | D30: 18 | E30: =IF(COUNTIF(Songs!$C:$C,C30)>0,"","NO") | F30: Worship | G30: Live | J30: YES
A31: 30 | B31: 2004 | C31: Faithful | D31: 12 | E31: =IF(COUNTIF(Songs!$C:$C,C31)>0,"","NO") | F31: Worship | G31: Live | J31: YES
A32: 31 | B32: 2004 | C32: For All You've Done | D32: 15 | E32: =IF(COUNTIF(Songs!$C:$C,C32)>0,"","NO") | F32: Worship | G32: Live | J32: YES
A33: 32 | B33: 2004 | C33: More Than Life | D33: 15 | E33: =IF(COUNTIF(Songs!$C:$C,C33)>0,"","NO") | F33: United | G33: Live | J33: YES
A34: 33 | B34: 2004 | C34: Unified, Praise | D34: 11 | E34: =IF(COUNTIF(Songs!$C:$C,C34)>0,"","NO") | F34: Worship | G34: Live | J34: YES
A35: 34 | B35: 2005 | C35: God He Reigns | D35: 15 | E35: =IF(COUNTIF(Songs!$C:$C,C35)>0,"","NO") | F35: Worship | G35: Live | J35: YES
A36: 35 | B36: 2005 | C36: Look to You | D36: 13 | E36: =IF(COUNTIF(Songs!$C:$C,C36)>0,"","NO") | F36: United | G36: Live | J36: YES
A37: 36 | B37: 2005 | C37: Ultimate Worship, Hillsong | D37: 17 | E37: =IF(COUNTIF(Songs!$C:$C,C37)>0,"","NO") -> NO | F37: Worship | G37: Live | H37: Compilation | I37: Exclude | J37: YES
A38: 37 | B38: 2006 | C38: Celebrating Christmas | D38: 12 | E38: =IF(COUNTIF(Songs!$C:$C,C38)>0,"","NO") | F38: Worship | G38: Live | H38: Christmas | J38: YES
A39: 38 | B39: 2006 | C39: Mighty to Save | D39: 14 | E39: =IF(COUNTIF(Songs!$C:$C,C39)>0,"","NO") | F39: Worship | G39: Live | J39: YES
A40: 39 | B40: 2006 | C40: Songs For Communion | D40: 14 | E40: =IF(COUNTIF(Songs!$C:$C,C40)>0,"","NO") | F40: Worship | G40: Live | J40: YES
A41: 40 | B41: 2006 | C41: United We Stand | D41: 17 | E41: =IF(COUNTIF(Songs!$C:$C,C41)>0,"","NO") | F41: United | G41: Live | J41: YES
A42: 41 | B42: 2007 | C42: All of the Above | D42: 14 | E42: =IF(COUNTIF(Songs!$C:$C,C42)>0,"","NO") | F42: United | G42: Studio | J42: YES
A43: 42 | B43: 2007 | C43: Saviour King | D43: 14 | E43: =IF(COUNTIF(Songs!$C:$C,C43)>0,"","NO") | F43: Worship | G43: Live | J43: YES
...

Sheet Songs
A1: # | B1: Year | C1: Album | D1: Track | E1: Title | F1: Author | G1: Key | H1: CCLI# | I1: Notes | J1: Worship leader(s) | K1: Length | L1: In MC?
A2: =INDEX(Albums!$A:$A, MATCH(C2,Albums!$C:$C,0)) -> 1 | B2: =INDEX(Albums!$B:$B, MATCH(C2,Albums!$C:$C,0)) -> 1988 | C2: Spirit and Truth | D2: 1 | E2: Heaven Suffers Violence | F2: Brian Houston | L2: =IF(AND(ISNUMBER(H2), COUNTIF([1]Songs!$L:$L,H2)>0),"YES","")
A3: =INDEX(Albums!$A:$A, MATCH(C3,Albums!$C:$C,0)) -> 1 | B3: =INDEX(Albums!$B:$B, MATCH(C3,Albums!$C:$C,0)) -> 1988 | C3: Spirit and Truth | D3: 2 | E3: With Your Love | F3: Geoff Bullock | L3: =IF(AND(ISNUMBER(H3), COUNTIF([1]Songs!$L:$L,H3)>0),"YES","")
A4: =INDEX(Albums!$A:$A, MATCH(C4,Albums!$C:$C,0)) -> 1 | B4: =INDEX(Albums!$B:$B, MATCH(C4,Albums!$C:$C,0)) -> 1988 | C4: Spirit and Truth | D4: 3 | E4: We're Not Looking Back | F4: Geoff Bullock | L4: =IF(AND(ISNUMBER(H4), COUNTIF([1]Songs!$L:$L,H4)>0),"YES","")
A5: =INDEX(Albums!$A:$A, MATCH(C5,Albums!$C:$C,0)) -> 1 | B5: =INDEX(Albums!$B:$B, MATCH(C5,Albums!$C:$C,0)) -> 1988 | C5: Spirit and Truth | D5: 4 | E5: I Will Lift My Voice | F5: Geoff Bullock | L5: =IF(AND(ISNUMBER(H5), COUNTIF([1]Songs!$L:$L,H5)>0),"YES","")
A6: =INDEX(Albums!$A:$A, MATCH(C6,Albums!$C:$C,0)) -> 1 | B6: =INDEX(Albums!$B:$B, MATCH(C6,Albums!$C:$C,0)) -> 1988 | C6: Spirit and Truth | D6: 5 | E6: We've Come To Worship The Lord | F6: Geoff Bullock | L6: =IF(AND(ISNUMBER(H6), COUNTIF([1]Songs!$L:$L,H6)>0),"YES","")
A7: =INDEX(Albums!$A:$A, MATCH(C7,Albums!$C:$C,0)) -> 1 | B7: =INDEX(Albums!$B:$B, MATCH(C7,Albums!$C:$C,0)) -> 1988 | C7: Spirit and Truth | D7: 6 | E7: Lift High His Name | F7: Geoff Bullock | L7: =IF(AND(ISNUMBER(H7), COUNTIF([1]Songs!$L:$L,H7)>0),"YES","")
A8: =INDEX(Albums!$A:$A, MATCH(C8,Albums!$C:$C,0)) -> 1 | B8: =INDEX(Albums!$B:$B, MATCH(C8,Albums!$C:$C,0)) -> 1988 | C8: Spirit and Truth | D8: 7 | E8: The Power Of God | F8: Brian Houston, Geoff Bullock | L8: =IF(AND(ISNUMBER(H8), COUNTIF([1]Songs!$L:$L,H8)>0),"YES","")
A9: =INDEX(Albums!$A:$A, MATCH(C9,Albums!$C:$C,0)) -> 1 | B9: =INDEX(Albums!$B:$B, MATCH(C9,Albums!$C:$C,0)) -> 1988 | C9: Spirit and Truth | D9: 8 | E9: He Is The King | F9: Geoff Bullock | L9: =IF(AND(ISNUMBER(H9), COUNTIF([1]Songs!$L:$L,H9)>0),"YES","")
A10: =INDEX(Albums!$A:$A, MATCH(C10,Albums!$C:$C,0)) -> 1 | B10: =INDEX(Albums!$B:$B, MATCH(C10,Albums!$C:$C,0)) -> 1988 | C10: Spirit and Truth | D10: 9 | E10: We Will Not Bow To The World | F10: Brian Houston, Geoff Bullock | L10: =IF(AND(ISNUMBER(H10), COUNTIF([1]Songs!$L:$L,H10)>0),"YES","")
A11: =INDEX(Albums!$A:$A, MATCH(C11,Albums!$C:$C,0)) -> 1 | B11: =INDEX(Albums!$B:$B, MATCH(C11,Albums!$C:$C,0)) -> 1988 | C11: Spirit and Truth | D11: 10 | E11: The Heavens Shall Declare | F11: Geoff Bullock | L11: =IF(AND(ISNUMBER(H11), COUNTIF([1]Songs!$L:$L,H11)>0),"YES","")
A12: =INDEX(Albums!$A:$A, MATCH(C12,Albums!$C:$C,0)) -> 1 | B12: =INDEX(Albums!$B:$B, MATCH(C12,Albums!$C:$C,0)) -> 1988 | C12: Spirit and Truth | D12: 11 | E12: The Lord's Prayer | F12: Rob Eastwood | L12: =IF(AND(ISNUMBER(H12), COUNTIF([1]Songs!$L:$L,H12)>0),"YES","")
A13: =INDEX(Albums!$A:$A, MATCH(C13,Albums!$C:$C,0)) -> 2 | B13: =INDEX(Albums!$B:$B, MATCH(C13,Albums!$C:$C,0)) -> 1990 | C13: Show Your Glory | D13: 1 | E13: Without Him | K13: 0.18819444 | L13: =IF(AND(ISNUMBER(H13), COUNTIF([1]Songs!$L:$L,H13)>0),"YES","")
A14: =INDEX(Albums!$A:$A, MATCH(C14,Albums!$C:$C,0)) -> 2 | B14: =INDEX(Albums!$B:$B, MATCH(C14,Albums!$C:$C,0)) -> 1990 | C14: Show Your Glory | D14: 2 | E14: The Enemy's Defeated | K14: 0.12430556 | L14: =IF(AND(ISNUMBER(H14), COUNTIF([1]Songs!$L:$L,H14)>0),"YES","")
A15: =INDEX(Albums!$A:$A, MATCH(C15,Albums!$C:$C,0)) -> 2 | B15: =INDEX(Albums!$B:$B, MATCH(C15,Albums!$C:$C,0)) -> 1990 | C15: Show Your Glory | D15: 3 | E15: Revival | K15: 0.17152778 | L15: =IF(AND(ISNUMBER(H15), COUNTIF([1]Songs!$L:$L,H15)>0),"YES","")
A16: =INDEX(Albums!$A:$A, MATCH(C16,Albums!$C:$C,0)) -> 2 | B16: =INDEX(Albums!$B:$B, MATCH(C16,Albums!$C:$C,0)) -> 1990 | C16: Show Your Glory | D16: 4 | E16: Sanctify | K16: 0.10138889 | L16: =IF(AND(ISNUMBER(H16), COUNTIF([1]Songs!$L:$L,H16)>0),"YES","")
A17: =INDEX(Albums!$A:$A, MATCH(C17,Albums!$C:$C,0)) -> 2 | B17: =INDEX(Albums!$B:$B, MATCH(C17,Albums!$C:$C,0)) -> 1990 | C17: Show Your Glory | D17: 5 | E17: Armed And Dangerous | K17: 0.11736111 | L17: =IF(AND(ISNUMBER(H17), COUNTIF([1]Songs!$L:$L,H17)>0),"YES","")
A18: =INDEX(Albums!$A:$A, MATCH(C18,Albums!$C:$C,0)) -> 2 | B18: =INDEX(Albums!$B:$B, MATCH(C18,Albums!$C:$C,0)) -> 1990 | C18: Show Your Glory | D18: 6 | E18: Fire | K18: 0.15138889 | L18: =IF(AND(ISNUMBER(H18), COUNTIF([1]Songs!$L:$L,H18)>0),"YES","")
A19: =INDEX(Albums!$A:$A, MATCH(C19,Albums!$C:$C,0)) -> 2 | B19: =INDEX(Albums!$B:$B, MATCH(C19,Albums!$C:$C,0)) -> 1990 | C19: Show Your Glory | D19: 7 | E19: Praise Him | K19: 0.12777778 | L19: =IF(AND(ISNUMBER(H19), COUNTIF([1]Songs!$L:$L,H19)>0),"YES","")
A20: =INDEX(Albums!$A:$A, MATCH(C20,Albums!$C:$C,0)) -> 2 | B20: =INDEX(Albums!$B:$B, MATCH(C20,Albums!$C:$C,0)) -> 1990 | C20: Show Your Glory | D20: 8 | E20: Show Your Glory | K20: 0.23333333 | L20: =IF(AND(ISNUMBER(H20), COUNTIF([1]Songs!$L:$L,H20)>0),"YES","")
A21: =INDEX(Albums!$A:$A, MATCH(C21,Albums!$C:$C,0)) -> 2 | B21: =INDEX(Albums!$B:$B, MATCH(C21,Albums!$C:$C,0)) -> 1990 | C21: Show Your Glory | D21: 9 | E21: I Am Not Ashamed | K21: 0.19166667 | L21: =IF(AND(ISNUMBER(H21), COUNTIF([1]Songs!$L:$L,H21)>0),"YES","")
A22: =INDEX(Albums!$A:$A, MATCH(C22,Albums!$C:$C,0)) -> 2 | B22: =INDEX(Albums!$B:$B, MATCH(C22,Albums!$C:$C,0)) -> 1990 | C22: Show Your Glory | D22: 10 | E22: Lord Take My Eyes | K22: 0.16666667 | L22: =IF(AND(ISNUMBER(H22), COUNTIF([1]Songs!$L:$L,H22)>0),"YES","")
A23: =INDEX(Albums!$A:$A, MATCH(C23,Albums!$C:$C,0)) -> 2 | B23: =INDEX(Albums!$B:$B, MATCH(C23,Albums!$C:$C,0)) -> 1990 | C23: Show Your Glory | D23: 11 | E23: Blessing | K23: 0.24930556 | L23: =IF(AND(ISNUMBER(H23), COUNTIF([1]Songs!$L:$L,H23)>0),"YES","")
A24: =INDEX(Albums!$A:$A, MATCH(C24,Albums!$C:$C,0)) -> 2 | B24: =INDEX(Albums!$B:$B, MATCH(C24,Albums!$C:$C,0)) -> 1990 | C24: Show Your Glory | D24: 12 | E24: Holy | K24: 0.21180556 | L24: =IF(AND(ISNUMBER(H24), COUNTIF([1]Songs!$L:$L,H24)>0),"YES","")
... A26: =INDEX(Albums!$A:$A, MATCH(C26,Albums!$C:$C,0)) -> 2 | B26: =INDEX(Albums!$B:$B, MATCH(C26,Albums!$C:$C,0)) -> 1990 | C26: Show Your Glory | D26: 14 | E26: Show Your Glory (Alternate Mix) | K26: 0.23402778 | L26: =IF(AND(ISNUMBER(H26), COUNTIF([1]Songs!$L:$L,H26)>0),"YES","")
A27: =INDEX(Albums!$A:$A, MATCH(C27,Albums!$C:$C,0)) -> 3 | B27: =INDEX(Albums!$B:$B, MATCH(C27,Albums!$C:$C,0)) -> 1992 | C27: The Power of Your Love | D27: 1 | E27: The Time Has Come | F27: Geoff Bullock | L27: =IF(AND(ISNUMBER(H27), COUNTIF([1]Songs!$L:$L,H27)>0),"YES","")
A28: =INDEX(Albums!$A:$A, MATCH(C28,Albums!$C:$C,0)) -> 3 | B28: =INDEX(Albums!$B:$B, MATCH(C28,Albums!$C:$C,0)) -> 1992 | C28: The Power of Your Love | D28: 2 | E28: We Will Rise | F28: Bullock | L28: =IF(AND(ISNUMBER(H28), COUNTIF([1]Songs!$L:$L,H28)>0),"YES","")
A29: =INDEX(Albums!$A:$A, MATCH(C29,Albums!$C:$C,0)) -> 3 | B29: =INDEX(Albums!$B:$B, MATCH(C29,Albums!$C:$C,0)) -> 1992 | C29: The Power of Your Love | D29: 3 | E29: You Placed Your Love | F29: Bullock | L29: =IF(AND(ISNUMBER(H29), COUNTIF([1]Songs!$L:$L,H29)>0),"YES","")
A30: =INDEX(Albums!$A:$A, MATCH(C30,Albums!$C:$C,0)) -> 3 | B30: =INDEX(Albums!$B:$B, MATCH(C30,Albums!$C:$C,0)) -> 1992 | C30: The Power of Your Love | D30: 4 | E30: Your Love | F30: Bullock | L30: =IF(AND(ISNUMBER(H30), COUNTIF([1]Songs!$L:$L,H30)>0),"YES","")
A31: =INDEX(Albums!$A:$A, MATCH(C31,Albums!$C:$C,0)) -> 3 | B31: =INDEX(Albums!$B:$B, MATCH(C31,Albums!$C:$C,0)) -> 1992 | C31: The Power of Your Love | D31: 5 | E31: Blessed Be | F31: Bullock | L31: =IF(AND(ISNUMBER(H31), COUNTIF([1]Songs!$L:$L,H31)>0),"YES","")
A32: =INDEX(Albums!$A:$A, MATCH(C32,Albums!$C:$C,0)) -> 3 | B32: =INDEX(Albums!$B:$B, MATCH(C32,Albums!$C:$C,0)) -> 1992 | C32: The Power of Your Love | D32: 6 | E32: You Are My Rock | F32: Bullock | L32: =IF(AND(ISNUMBER(H32), COUNTIF([1]Songs!$L:$L,H32)>0),"YES","")
A33: =INDEX(Albums!$A:$A, MATCH(C33,Albums!$C:$C,0)) -> 3 | B33: =INDEX(Albums!$B:$B, MATCH(C33,Albums!$C:$C,0)) -> 1992 | C33: The Power of Your Love | D33: 7 | E33: Hear Me Calling | F33: Bullock | L33: =IF(AND(ISNUMBER(H33), COUNTIF([1]Songs!$L:$L,H33)>0),"YES","")
A34: =INDEX(Albums!$A:$A, MATCH(C34,Albums!$C:$C,0)) -> 3 | B34: =INDEX(Albums!$B:$B, MATCH(C34,Albums!$C:$C,0)) -> 1992 | C34: The Power of Your Love | D34: 8 | E34: Refresh My Heart | F34: Bullock | L34: =IF(AND(ISNUMBER(H34), COUNTIF([1]Songs!$L:$L,H34)>0),"YES","")
A35: =INDEX(Albums!$A:$A, MATCH(C35,Albums!$C:$C,0)) -> 3 | B35: =INDEX(Albums!$B:$B, MATCH(C35,Albums!$C:$C,0)) -> 1992 | C35: The Power of Your Love | D35: 9 | E35: The Power of Your Love | F35: Bullock | L35: =IF(AND(ISNUMBER(H35), COUNTIF([1]Songs!$L:$L,H35)>0),"YES","")
A36: =INDEX(Albums!$A:$A, MATCH(C36,Albums!$C:$C,0)) -> 3 | B36: =INDEX(Albums!$B:$B, MATCH(C36,Albums!$C:$C,0)) -> 1992 | C36: The Power of Your Love | D36: 10 | E36: Lord We Come | F36: Bullock | L36: =IF(AND(ISNUMBER(H36), COUNTIF([1]Songs!$L:$L,H36)>0),"YES","")
A37: =INDEX(Albums!$A:$A, MATCH(C37,Albums!$C:$C,0)) -> 3 | B37: =INDEX(Albums!$B:$B, MATCH(C37,Albums!$C:$C,0)) -> 1992 | C37: The Power of Your Love | D37: 11 | E37: I Will Worship You | F37: Bullock | L37: =IF(AND(ISNUMBER(H37), COUNTIF([1]Songs!$L:$L,H37)>0),"YES","")
A38: =INDEX(Albums!$A:$A, MATCH(C38,Albums!$C:$C,0)) -> 3 | B38: =INDEX(Albums!$B:$B, MATCH(C38,Albums!$C:$C,0)) -> 1992 | C38: The Power of Your Love | D38: 12 | E38: You Are My God | F38: Bullock & Gail Dunshea | L38: =IF(AND(ISNUMBER(H38), COUNTIF([1]Songs!$L:$L,H38)>0),"YES","")
... A42: =INDEX(Albums!$A:$A, MATCH(C42,Albums!$C:$C,0)) -> 3 | B42: =INDEX(Albums!$B:$B, MATCH(C42,Albums!$C:$C,0)) -> 1992 | C42: The Power of Your Love | D42: 16 | E42: The Great Southland | F42: Bullock | L42: =IF(AND(ISNUMBER(H42), COUNTIF([1]Songs!$L:$L,H42)>0),"YES","")
A43: =INDEX(Albums!$A:$A, MATCH(C43,Albums!$C:$C,0)) -> 4 | B43: =INDEX(Albums!$B:$B, MATCH(C43,Albums!$C:$C,0)) -> 1993 | C43: Stone's Been Rolled Away | D43: 1 | E43: The Stone's Been Rolled Away | F43: Geoff Bullock | J43: Darlene Zschech, b. Geoff Bullock | L43: =IF(AND(ISNUMBER(H43), COUNTIF([1]Songs!$L:$L,H43)>0),"YES","")
A44: =INDEX(Albums!$A:$A, MATCH(C44,Albums!$C:$C,0)) -> 4 | B44: =INDEX(Albums!$B:$B, MATCH(C44,Albums!$C:$C,0)) -> 1993 | C44: Stone's Been Rolled Away | D44: 2 | E44: You Give Me Shelter | F44: Geoff Bullock | J44: Sylvia Pettit & Steve McPherson | L44: =IF(AND(ISNUMBER(H44), COUNTIF([1]Songs!$L:$L,H44)>0),"YES","")
...

Sheet Rejected (Compilations)
A1: Year | B1: Album | C1: Band | D1: Song # | E1: Title | F1: Author | G1: Worship leader(s) | H1: Length | I1: CCLI# | J1: Original Key | K1: Notes | L1: In MC?
A2: 2016 | B2: Of Dirt and Grace: Live from the Land | C2: Worship | D2: 1 | E2: Here Now (Madness) | F2: Joel Houston, Michael Guy Chislett | G2: Joel Houston, Taya Smith, Jad Gillies | H2: 0.31527778 | L2: =IF(AND(ISNUMBER(I2), COUNTIF([1]Songs!$L:$L,I2)>0),"YES","")
A3: 2016 | B3: Of Dirt and Grace: Live from the Land | C3: Worship | D3: 2 | E3: Say the Word | F3: Houston | G3: Jad Gillies | H3: 0.15486111 | L3: =IF(AND(ISNUMBER(I3), COUNTIF([1]Songs!$L:$L,I3)>0),"YES","")
A4: 2016 | B4: Of Dirt and Grace: Live from the Land | C4: Worship | D4: 3 | E4: Heart Like Heaven (Falling) | F4: Matt Crocker, Houston | G4: Matt Crocker | H4: 0.34305556 | L4: =IF(AND(ISNUMBER(I4), COUNTIF([1]Songs!$L:$L,I4)>0),"YES","")
A5: 2016 | B5: Of Dirt and Grace: Live from the Land | C5: Worship | D5: 4 | E5: Touch the Sky | F5: Houston, Dylan Thomas, Chislett | G5: Taya Smith[4] | H5: 0.17013889 | L5: =IF(AND(ISNUMBER(I5), COUNTIF([1]Songs!$L:$L,I5)>0),"YES","")
A6: 2016 | B6: Of Dirt and Grace: Live from the Land | C6: Worship | D6: 5 | E6: Street Called Mercy | F6: Crocker, Houston | G6: Jonathon Douglass, Taya Smith, Matt Crocker | H6: 0.16458333 | L6: =IF(AND(ISNUMBER(I6), COUNTIF([1]Songs!$L:$L,I6)>0),"YES","")
A7: 2016 | B7: Of Dirt and Grace: Live from the Land | C7: Worship | D7: 6 | E7: When I Lost My Heart to You (Hallelujah) | F7: Houston | G7: Taya Smith, Matt Crocker | H7: 0.34791667 | L7: =IF(AND(ISNUMBER(I7), COUNTIF([1]Songs!$L:$L,I7)>0),"YES","")
A8: 2016 | B8: Of Dirt and Grace: Live from the Land | C8: Worship | D8: 7 | E8: Even When It Hurts (Praise Song) | F8: Houston | G8: Taya Smith[4] | H8: 0.24305556 | L8: =IF(AND(ISNUMBER(I8), COUNTIF([1]Songs!$L:$L,I8)>0),"YES","")
A9: 2016 | B9: Of Dirt and Grace: Live from the Land | C9: Worship | D9: 8 | E9: Prince of Peace | F9: Thomas, Houston, Crocker | G9: Taya Smith[12][4] | H9: 0.34166667 | L9: =IF(AND(ISNUMBER(I9), COUNTIF([1]Songs!$L:$L,I9)>0),"YES","")
A10: 2016 | B10: Of Dirt and Grace: Live from the Land | C10: Worship | D10: 9 | E10: Empires | F10: Houston, Thomas, Chris Davenport, Ben Tennikoff | G10: Joel Houston | H10: 0.30347222 | L10: =IF(AND(ISNUMBER(I10), COUNTIF([1]Songs!$L:$L,I10)>0),"YES","")
A11: 2016 | B11: Of Dirt and Grace: Live from the Land | C11: Worship | D11: 10 | E11: Rule | F11: Crocker, Houston, Tennikoff | G11: Matt Crocker | H11: 0.16458333 | L11: =IF(AND(ISNUMBER(I11), COUNTIF([1]Songs!$L:$L,I11)>0),"YES","")
A12: 2016 | B12: Of Dirt and Grace: Live from the Land | C12: Worship | D12: 11 | E12: Captain | F12: Benjamin Hastings, Seth Simmons | G12: Jad Gillies | H12: 0.26666667 | L12: =IF(AND(ISNUMBER(I12), COUNTIF([1]Songs!$L:$L,I12)>0),"YES","")
A13: 2016 | B13: Of Dirt and Grace: Live from the Land | C13: Worship | D13: 12 | E13: Closer Than You Know | F13: Houston, Crocker, Chislett | G13: Joel Houston, Taya Smith | H13: 0.41875 | L13: =IF(AND(ISNUMBER(I13), COUNTIF([1]Songs!$L:$L,I13)>0),"YES","")
... A29: 2012 | B29: Live in Miami: Welcome to the Aftermath | C29: Worship | D29: 4 | E29: Search My Heart | F29: Joel Houston, Matt Crocker | G29: Jad Gillies | H29: 0.29375 | L29: =IF(AND(ISNUMBER(I29), COUNTIF([1]Songs!$L:$L,I29)>0),"YES","")
A30: 2012 | B30: Live in Miami: Welcome to the Aftermath | C30: Worship | D30: 5 | E30: Mighty to Save | F30: Reuben Morgan, Ben Fielding | G30: Joel Houston | H30: 0.21666667 | K30: Popular | L30: =IF(AND(ISNUMBER(I30), COUNTIF([1]Songs!$L:$L,I30)>0),"YES","")
A31: 2012 | B31: Live in Miami: Welcome to the Aftermath | C31: Worship | D31: 6 | E31: Hosanna | F31: Brooke Fraser | G31: Hayley Law | H31: 0.26388889 | L31: =IF(AND(ISNUMBER(I31), COUNTIF([1]Songs!$L:$L,I31)>0),"YES","")
A32: 2012 | B32: Live in Miami: Welcome to the Aftermath | C32: Worship | D32: 7 | E32: All I Need Is You | F32: Marty Sampson | G32: Jad Gillies | H32: 0.24722222 | L32: =IF(AND(ISNUMBER(I32), COUNTIF([1]Songs!$L:$L,I32)>0),"YES","")
A33: 2012 | B33: Live in Miami: Welcome to the Aftermath | C33: Worship | D33: 8 | E33: Bones | F33: Joel Houston, Jill McCloghry | G33: Jill McCloghry | H33: 0.17152778 | L33: =IF(AND(ISNUMBER(I33), COUNTIF([1]Songs!$L:$L,I33)>0),"YES","")
A34: 2012 | B34: Live in Miami: Welcome to the Aftermath | C34: Worship | D34: 9 | E34: Nova | F34: Joel Houston, Matt Crocker, Michael Guy Chislett | G34: Matt Crocker | H34: 0.25138889 | L34: =IF(AND(ISNUMBER(I34), COUNTIF([1]Songs!$L:$L,I34)>0),"YES","")
A35: 2012 | B35: Live in Miami: Welcome to the Aftermath | C35: Worship | D35: 10 | E35: Aftermath | F35: Joel Houston | G35: Joel Houston | H35: 0.3375 | L35: =IF(AND(ISNUMBER(I35), COUNTIF([1]Songs!$L:$L,I35)>0),"YES","")
A36: 2012 | B36: Live in Miami: Welcome to the Aftermath | C36: Worship | D36: 11 | E36: Freedom Is Here / Shout Unto God | F36: Reuben Morgan, Scott Ligertwood / Joel Houston, Marty Sampson | G36: Jad Gillies / Joel Houston | H36: 0.32013889 | L36: =IF(AND(ISNUMBER(I36), COUNTIF([1]Songs!$L:$L,I36)>0),"YES","")
A37: 2012 | B37: Live in Miami: Welcome to the Aftermath | C37: Worship | D37: 12 | E37: Like An Avalanche | F37: Joel Houston, Dylan Thomas | G37: Hayley Law | H37: 0.26527778 | L37: =IF(AND(ISNUMBER(I37), COUNTIF([1]Songs!$L:$L,I37)>0),"YES","")
A38: 2012 | B38: Live in Miami: Welcome to the Aftermath | C38: Worship | D38: 13 | E38: Rhythms of Grace | F38: Chris Davenport, Dean Ussher | G38: Jad Gillies | H38: 0.26527778 | L38: =IF(AND(ISNUMBER(I38), COUNTIF([1]Songs!$L:$L,I38)>0),"YES","")
A39: 2012 | B39: Live in Miami: Welcome to the Aftermath | C39: Worship | D39: 14 | E39: Oh You Bring | F39: Matt Crocker | G39: Matt Crocker | H39: 0.26666667 | L39: =IF(AND(ISNUMBER(I39), COUNTIF([1]Songs!$L:$L,I39)>0),"YES","")
A40: 2012 | B40: Live in Miami: Welcome to the Aftermath | C40: Worship | D40: 15 | E40: The Stand | F40: Joel Houston | G40: Joel Houston | H40: 0.20416667 | L40: =IF(AND(ISNUMBER(I40), COUNTIF([1]Songs!$L:$L,I40)>0),"YES","")
A41: 2012 | B41: Live in Miami: Welcome to the Aftermath | C41: Worship | D41: 16 | E41: From the Inside Out | F41: Joel Houston | G41: Joel Houston | H41: 0.22083333 | L41: =IF(AND(ISNUMBER(I41), COUNTIF([1]Songs!$L:$L,I41)>0),"YES","")
A42: 2012 | B42: Live in Miami: Welcome to the Aftermath | C42: Worship | D42: 17 | E42: A Song to Sing... | F42: Joel Houston | G42: Joel Houston | H42: 0.11666667 | L42: =IF(AND(ISNUMBER(I42), COUNTIF([1]Songs!$L:$L,I42)>0),"YES","")
... A77: 2008 | B77: The I Heart Revolution: With Hearts as One | C77: Worship | D77: 30 | E77: Solution | F77: Joel Houston and Matt Crocker | G77: Joel Houston | H77: 0.24652778 | L77: =IF(AND(ISNUMBER(I77), COUNTIF([1]Songs!$L:$L,I77)>0),"YES","")
