Workbook

Sheet Statistics
A1: Category | B1: Count | D1: Volume | E1: Category | F1: Count
A2: TWI Total | B2: 232 | D2: Volume 1 | E2: Vol. 1-12 | F2: 124
A3: ALL CCWS | B3: 186 | E3: Hymns | F3: 20
A4: ALL Other | B4: 163 | E4: Psalms | F4: 12
F5: =SUM(F2:F4) -> 156
A6: Category | B6: Count
A7: Vol. 1-12 | B7: 124 | D7: Volume 2 | E7: Vol. 13-23 | F7: 98
A8: Vol. 13-23 | B8: 98 | E8: TWI Special | F8: 10
A9: TWI Special | B9: 10 | E9: WI Lite | F9: 10
A10: WI Lite | B10: 10 | E10: WI Singles | F10: 1
A11: WI Singles | B11: 1 | E11: Christmas | F11: 20
A12: Hymns | B12: 20 | E12: From CCWS Xmas | F12: 6
A13: Christmas | B13: 20 | F13: =SUM(F7:F12) -> 145
A14: Psalms | B14: 12
A15: From CCWS | B15: 94 | D15: Extra | E15: From CCWS | F15: 94
A16: From CCWS Xmas | B16: 6 | E16: Other | F16: 69
A17: Other | B17: 69 | F17: =SUM(F15:F16) -> 163
B18: =SUM(B7:B17) -> 464

Sheet Album
A1: Id | B1: Artist | C1: Title | D1: Year | E1: TrackCount | F1: Type | G1: Category | H1: Notes | I1: Path | J1: Exclude | K1: In List? | L1: Release Date
A2: 1 | B2: Shane & Shane | C2: Psalms, Vol. 1 | D2: 2002 | E2: 13 | F2: Studio | G2: Psalms | H2: Not on TWI | I2: AlbumArt/600/Psalms, Vol. 1.jpg | J2: Exclude | K2: =IF(COUNTIF(Track!$B:$B,C2)>0,"","NO") | L2: 37411
A3: 2 | B3: Shane & Shane | C3: Carry Away | D3: 2003 | E3: 13 | F3: Studio | G3: Original | I3: AlbumArt/600/Carry Away.jpg | J3: Exclude | K3: =IF(COUNTIF(Track!$B:$B,C3)>0,"","NO") | L3: April 22, 2003
A4: 3 | B4: Shane & Shane | C4: Clean | D4: 2004 | E4: 11 | F4: Studio | G4: Original | I4: AlbumArt/600/Clean.jpg | J4: Exclude | K4: =IF(COUNTIF(Track!$B:$B,C4)>0,"","NO") | L4: October 19, 2004
A5: 4 | B5: Shane & Shane | C5: Upstairs | D5: 2004 | E5: 10 | F5: Studio | G5: Original | I5: AlbumArt/600/Upstairs.jpg | J5: Exclude | K5: =IF(COUNTIF(Track!$B:$B,C5)>0,"","NO") | L5: May 18, 2004
A6: 5 | B6: Shane & Shane | C6: Pages | D6: 2007 | E6: 15 | F6: Studio | G6: Original | I6: AlbumArt/600/Pages.jpg | J6: Exclude | K6: =IF(COUNTIF(Track!$B:$B,C6)>0,"","NO") | L6: August 28, 2007
A7: 6 | B7: Shane & Shane | C7: Glory in the Highest, A Christmas Record | D7: 2008 | E7: 10 | F7: Studio | G7: Christmas | H7: Not on TWI | I7: AlbumArt/600/Glory in the Highest, A Christmas Record.jpg | J7: Exclude | K7: =IF(COUNTIF(Track!$B:$B,C7)>0,"","NO") | L7: 39735
A8: 7 | B8: Shane & Shane | C8: Everything Is Different | D8: 2009 | E8: 15 | F8: Studio | G8: Original | I8: AlbumArt/600/Everything Is Different.jpg | J8: Exclude | K8: =IF(COUNTIF(Track!$B:$B,C8)>0,"","NO") | L8: 40120
A9: 8 | B9: Shane & Shane | C9: Dare 2 Share, Unending Worship | D9: 2010 | E9: 10 | F9: Studio | G9: Original | I9: AlbumArt/600/Dare 2 Share, Unending Worship.jpg | J9: Exclude | K9: =IF(COUNTIF(Track!$B:$B,C9)>0,"","NO") | L9: 40470
A10: 9 | B10: Shane & Shane | C10: The One You Need | D10: 2011 | E10: 12 | F10: Studio | G10: Original | I10: AlbumArt/600/The One You Need.jpg | J10: Exclude | K10: =IF(COUNTIF(Track!$B:$B,C10)>0,"","NO") | L10: 40820
A11: 10 | B11: Shane & Shane | C11: Bring Your Nothing | D11: 2013 | E11: 11 | F11: Studio | G11: Original | I11: AlbumArt/600/Bring Your Nothing.jpg | J11: Exclude | K11: =IF(COUNTIF(Track!$B:$B,C11)>0,"","NO") | L11: 41408
A12: 11 | B12: Shane & Shane | C12: The Worship Initiative, Vol. 01 | D12: 2014 | E12: 10 | F12: Studio | I12: AlbumArt/600/The Worship Initiative, Vol. 01.jpg | K12: =IF(COUNTIF(Track!$B:$B,C12)>0,"","NO") | L12: 41765
A13: 12 | B13: Shane & Shane | C13: The Worship Initiative, Vol. 02 | D13: 2014 | E13: 10 | F13: Studio | I13: AlbumArt/600/The Worship Initiative, Vol. 02.jpg | K13: =IF(COUNTIF(Track!$B:$B,C13)>0,"","NO") | L13: 41786
A14: 13 | B14: Shane & Shane | C14: The Worship Initiative, Vol. 03 | D14: 2014 | E14: 10 | F14: Studio | I14: AlbumArt/600/The Worship Initiative, Vol. 03.jpg | K14: =IF(COUNTIF(Track!$B:$B,C14)>0,"","NO") | L14: 41807
A15: 14 | B15: Shane & Shane | C15: The Worship Initiative, Vol. 04 | D15: 2014 | E15: 10 | F15: Studio | I15: AlbumArt/600/The Worship Initiative, Vol. 04.jpg | K15: =IF(COUNTIF(Track!$B:$B,C15)>0,"","NO") | L15: 41828
A16: 15 | B16: Shane & Shane | C16: The Worship Initiative, Vol. 05 | D16: 2014 | E16: 10 | F16: Studio | I16: AlbumArt/600/The Worship Initiative, Vol. 05.jpg | K16: =IF(COUNTIF(Track!$B:$B,C16)>0,"","NO") | L16: 41849
A17: 16 | B17: Shane & Shane | C17: The Worship Initiative, Vol. 06 | D17: 2014 | E17: 10 | F17: Studio | I17: AlbumArt/600/The Worship Initiative, Vol. 06.jpg | K17: =IF(COUNTIF(Track!$B:$B,C17)>0,"","NO") | L17: 41872
A18: 17 | B18: Shane & Shane | C18: The Worship Initiative, Vol. 07 | D18: 2014 | E18: 10 | F18: Studio | I18: AlbumArt/600/The Worship Initiative, Vol. 07.jpg | K18: =IF(COUNTIF(Track!$B:$B,C18)>0,"","NO") | L18: 41891
A19: 18 | B19: Shane & Shane | C19: The Worship Initiative, Vol. 08 | D19: 2014 | E19: 10 | F19: Studio | I19: AlbumArt/600/The Worship Initiative, Vol. 08.jpg | K19: =IF(COUNTIF(Track!$B:$B,C19)>0,"","NO") | L19: 41912
A20: 19 | B20: Shane & Shane | C20: The Worship Initiative, Vol. 09 | D20: 2014 | E20: 10 | F20: Studio | I20: AlbumArt/600/The Worship Initiative, Vol. 09.jpg | K20: =IF(COUNTIF(Track!$B:$B,C20)>0,"","NO") | L20: 41933
A21: 20 | B21: Shane & Shane | C21: The Worship Initiative, Vol. 10 | D21: 2014 | E21: 10 | F21: Studio | I21: AlbumArt/600/The Worship Initiative, Vol. 10.jpg | K21: =IF(COUNTIF(Track!$B:$B,C21)>0,"","NO") | L21: 41961
A22: 21 | B22: Shane & Shane | C22: Psalms, Vol. 2 | D22: 2015 | E22: 12 | F22: Studio | G22: Psalms | I22: AlbumArt/600/Psalms, Vol. 2.jpg | K22: =IF(COUNTIF(Track!$B:$B,C22)>0,"","NO") | L22: 42300
A23: 22 | B23: Shane & Shane | C23: The Worship Initiative | D23: 2015 | E23: 10 | F23: Studio | H23: Kickstarter Project | I23: AlbumArt/600/The Worship Initiative.jpg | K23: =IF(COUNTIF(Track!$B:$B,C23)>0,"","NO") | L23: 42122
A24: 23 | B24: Shane & Shane | C24: Psalms (Live) | D24: 2016 | E24: 13 | F24: Live | G24: Psalms | H24: Not on TWI | I24: AlbumArt/600/Psalms (Live).jpg | J24: Exclude | K24: =IF(COUNTIF(Track!$B:$B,C24)>0,"","NO") | L24: 42698
A25: 24 | B25: Shane & Shane | C25: The Worship Initiative, Vol. 11 | D25: 2016 | E25: 11 | F25: Studio | I25: AlbumArt/600/The Worship Initiative, Vol. 11.jpg | K25: =IF(COUNTIF(Track!$B:$B,C25)>0,"","NO") | L25: 42643
A26: 25 | B26: Shane & Shane | C26: A Worship Initiative Christmas, Vol. 1 | D26: 2017 | E26: 10 | F26: Studio | G26: Christmas | I26: AlbumArt/600/A Worship Initiative Christmas, Vol. 1.jpg | K26: =IF(COUNTIF(Track!$B:$B,C26)>0,"","NO") | L26: 42839
A27: 26 | B27: Shane & Shane | C27: A Worship Initiative Christmas, Vol. 2 | D27: 2017 | E27: 10 | F27: Studio | G27: Christmas | I27: AlbumArt/600/A Worship Initiative Christmas, Vol. 2.jpg | K27: =IF(COUNTIF(Track!$B:$B,C27)>0,"","NO") | L27: 42839
A28: 27 | B28: Shane & Shane | C28: The Worship Initiative, Vol. 12 | D28: 2017 | E28: 13 | F28: Studio | I28: AlbumArt/600/The Worship Initiative, Vol. 12.jpg | K28: =IF(COUNTIF(Track!$B:$B,C28)>0,"","NO") | L28: 42839
A29: 28 | B29: Shane & Shane | C29: The Worship Initiative, Vol. 13 | D29: 2017 | E29: 5 | F29: Studio | I29: AlbumArt/600/The Worship Initiative, Vol. 13.jpg | K29: =IF(COUNTIF(Track!$B:$B,C29)>0,"","NO") | L29: 43000
A30: 29 | B30: Shane & Shane | C30: The Worship Initiative, Vol. 14 | D30: 2017 | E30: 5 | F30: Studio | I30: AlbumArt/600/The Worship Initiative, Vol. 14.jpg | K30: =IF(COUNTIF(Track!$B:$B,C30)>0,"","NO") | L30: 43039
A31: 30 | B31: Shane & Shane | C31: Hymns, Vol. 1 | D31: 2018 | E31: 10 | F31: Studio | G31: Hymns | I31: AlbumArt/600/Hymns, Vol. 1.jpg | K31: =IF(COUNTIF(Track!$B:$B,C31)>0,"","NO") | L31: 43350
A32: 31 | B32: Shane & Shane | C32: Hymns, Vol. 2 | D32: 2018 | E32: 10 | F32: Studio | G32: Hymns | I32: AlbumArt/600/Hymns, Vol. 2.jpg | K32: =IF(COUNTIF(Track!$B:$B,C32)>0,"","NO") | L32: 43700
A33: 32 | B33: Shane & Shane | C33: The Worship Initiative, Vol. 15 | D33: 2018 | E33: 5 | F33: Studio | I33: AlbumArt/600/The Worship Initiative, Vol. 15.jpg | K33: =IF(COUNTIF(Track!$B:$B,C33)>0,"","NO") | L33: 43145
A34: 33 | B34: Shane & Shane | C34: The Worship Initiative, Vol. 16 | D34: 2018 | E34: 10 | F34: Studio | I34: AlbumArt/600/The Worship Initiative, Vol. 16.jpg | K34: =IF(COUNTIF(Track!$B:$B,C34)>0,"","NO") | L34: 43297
A35: 34 | B35: Shane & Shane | C35: Hymns (Live) | D35: 2019 | E35: 13 | F35: Live | G35: Hymns | H35: Lots of duplicates | I35: AlbumArt/600/Hymns (Live).jpg | K35: =IF(COUNTIF(Track!$B:$B,C35)>0,"","NO") | L35: 43504
A36: 35 | B36: Shane & Shane | C36: A Worship Initiative Christmas, Vol. 3 | D36: 2019 | E36: 5 | F36: Studio | G36: Christmas | H36: Mainly duplicates of Vol. 1 | I36: AlbumArt/600/A Worship Initiative Christmas, Vol. 3.jpg | J36: Exclude | K36: =IF(COUNTIF(Track!$B:$B,C36)>0,"","NO") | L36: 43797
A37: 36 | B37: Shane & Shane | C37: The Worship Initiative, Vol. 17 | D37: 2019 | E37: 12 | F37: Studio | I37: AlbumArt/600/The Worship Initiative, Vol. 17.jpg | K37: =IF(COUNTIF(Track!$B:$B,C37)>0,"","NO") | L37: 43630
A38: 37 | B38: Shane & Shane | C38: The Worship Initiative, Vol. 18 | D38: 2020 | E38: 10 | F38: Studio | I38: AlbumArt/600/The Worship Initiative, Vol. 18.jpg | K38: =IF(COUNTIF(Track!$B:$B,C38)>0,"","NO") | L38: 43847
A39: 38 | B39: Shane & Shane | C39: The Worship Initiative, Vol. 19 | D39: 2020 | E39: 10 | F39: Studio | I39: AlbumArt/600/The Worship Initiative, Vol. 19.jpg | K39: =IF(COUNTIF(Track!$B:$B,C39)>0,"","NO") | L39: 43889
A40: 39 | B40: Shane & Shane | C40: The Worship Initiative, Vol. 20 | D40: 2020 | E40: 10 | F40: Studio | I40: AlbumArt/600/The Worship Initiative, Vol. 20.jpg | K40: =IF(COUNTIF(Track!$B:$B,C40)>0,"","NO") | L40: 43924
...

Sheet Track
A1: # | B1: Album | C1: Year | D1: Track | E1: Title | F1: AltTitle | G1: CcliNumber | H1: Author | I1: Key | J1: Tempo | K1: Performer | L1: Notes
A2: =INDEX(Album!$A:$A, MATCH(B2,Album!$C:$C,0)) -> 1 | B2: Psalms, Vol. 1 | C2: =INDEX(Album!$D:$D, MATCH(B2,Album!$C:$C,0)) -> 2002 | D2: 1 | E2: Breath of God
A3: =INDEX(Album!$A:$A, MATCH(B3,Album!$C:$C,0)) -> 1 | B3: Psalms, Vol. 1 | C3: =INDEX(Album!$D:$D, MATCH(B3,Album!$C:$C,0)) -> 2002 | D3: 2 | E3: Unto You
A4: =INDEX(Album!$A:$A, MATCH(B4,Album!$C:$C,0)) -> 1 | B4: Psalms, Vol. 1 | C4: =INDEX(Album!$D:$D, MATCH(B4,Album!$C:$C,0)) -> 2002 | D4: 3 | E4: Revive Me | F4: Psalm 143
A5: =INDEX(Album!$A:$A, MATCH(B5,Album!$C:$C,0)) -> 1 | B5: Psalms, Vol. 1 | C5: =INDEX(Album!$D:$D, MATCH(B5,Album!$C:$C,0)) -> 2002 | D5: 4 | E5: The Answer
A6: =INDEX(Album!$A:$A, MATCH(B6,Album!$C:$C,0)) -> 1 | B6: Psalms, Vol. 1 | C6: =INDEX(Album!$D:$D, MATCH(B6,Album!$C:$C,0)) -> 2002 | D6: 5 | E6: Psalm 13
A7: =INDEX(Album!$A:$A, MATCH(B7,Album!$C:$C,0)) -> 1 | B7: Psalms, Vol. 1 | C7: =INDEX(Album!$D:$D, MATCH(B7,Album!$C:$C,0)) -> 2002 | D7: 6 | E7: Psalm 145
A8: =INDEX(Album!$A:$A, MATCH(B8,Album!$C:$C,0)) -> 1 | B8: Psalms, Vol. 1 | C8: =INDEX(Album!$D:$D, MATCH(B8,Album!$C:$C,0)) -> 2002 | D8: 7 | E8: Waiting Room
A9: =INDEX(Album!$A:$A, MATCH(B9,Album!$C:$C,0)) -> 1 | B9: Psalms, Vol. 1 | C9: =INDEX(Album!$D:$D, MATCH(B9,Album!$C:$C,0)) -> 2002 | D9: 8 | E9: Job 19
A10: =INDEX(Album!$A:$A, MATCH(B10,Album!$C:$C,0)) -> 1 | B10: Psalms, Vol. 1 | C10: =INDEX(Album!$D:$D, MATCH(B10,Album!$C:$C,0)) -> 2002 | D10: 9 | E10: This Is the Day | F10: Psalm 118
A11: =INDEX(Album!$A:$A, MATCH(B11,Album!$C:$C,0)) -> 1 | B11: Psalms, Vol. 1 | C11: =INDEX(Album!$D:$D, MATCH(B11,Album!$C:$C,0)) -> 2002 | D11: 10 | E11: Praise the Name of Jesus
A12: =INDEX(Album!$A:$A, MATCH(B12,Album!$C:$C,0)) -> 1 | B12: Psalms, Vol. 1 | C12: =INDEX(Album!$D:$D, MATCH(B12,Album!$C:$C,0)) -> 2002 | D12: 11 | E12: We've Come to Declare
A13: =INDEX(Album!$A:$A, MATCH(B13,Album!$C:$C,0)) -> 1 | B13: Psalms, Vol. 1 | C13: =INDEX(Album!$D:$D, MATCH(B13,Album!$C:$C,0)) -> 2002 | D13: 12 | E13: You Said
A14: =INDEX(Album!$A:$A, MATCH(B14,Album!$C:$C,0)) -> 1 | B14: Psalms, Vol. 1 | C14: =INDEX(Album!$D:$D, MATCH(B14,Album!$C:$C,0)) -> 2002 | D14: 13 | E14: Hosea
A15: =INDEX(Album!$A:$A, MATCH(B15,Album!$C:$C,0)) -> 2 | B15: Carry Away | C15: =INDEX(Album!$D:$D, MATCH(B15,Album!$C:$C,0)) -> 2003 | D15: 1 | E15: Barren Land
A16: =INDEX(Album!$A:$A, MATCH(B16,Album!$C:$C,0)) -> 2 | B16: Carry Away | C16: =INDEX(Album!$D:$D, MATCH(B16,Album!$C:$C,0)) -> 2003 | D16: 2 | E16: Carry Away
A17: =INDEX(Album!$A:$A, MATCH(B17,Album!$C:$C,0)) -> 2 | B17: Carry Away | C17: =INDEX(Album!$D:$D, MATCH(B17,Album!$C:$C,0)) -> 2003 | D17: 3 | E17: Be Near
A18: =INDEX(Album!$A:$A, MATCH(B18,Album!$C:$C,0)) -> 2 | B18: Carry Away | C18: =INDEX(Album!$D:$D, MATCH(B18,Album!$C:$C,0)) -> 2003 | D18: 4 | E18: Mercy Reigns
A19: =INDEX(Album!$A:$A, MATCH(B19,Album!$C:$C,0)) -> 2 | B19: Carry Away | C19: =INDEX(Album!$D:$D, MATCH(B19,Album!$C:$C,0)) -> 2003 | D19: 5 | E19: Song of Surrender
A20: =INDEX(Album!$A:$A, MATCH(B20,Album!$C:$C,0)) -> 2 | B20: Carry Away | C20: =INDEX(Album!$D:$D, MATCH(B20,Album!$C:$C,0)) -> 2003 | D20: 6 | E20: I Want It All
A21: =INDEX(Album!$A:$A, MATCH(B21,Album!$C:$C,0)) -> 2 | B21: Carry Away | C21: =INDEX(Album!$D:$D, MATCH(B21,Album!$C:$C,0)) -> 2003 | D21: 7 | E21: When I Think About the Lord | H21: James Huey
A22: =INDEX(Album!$A:$A, MATCH(B22,Album!$C:$C,0)) -> 2 | B22: Carry Away | C22: =INDEX(Album!$D:$D, MATCH(B22,Album!$C:$C,0)) -> 2003 | D22: 8 | E22: Beauty for Ashes | H22: Barnard, Kendall Combs
A23: =INDEX(Album!$A:$A, MATCH(B23,Album!$C:$C,0)) -> 2 | B23: Carry Away | C23: =INDEX(Album!$D:$D, MATCH(B23,Album!$C:$C,0)) -> 2003 | D23: 9 | E23: Sweet Illumination | H23: Barnard, Shane Everett
A24: =INDEX(Album!$A:$A, MATCH(B24,Album!$C:$C,0)) -> 2 | B24: Carry Away | C24: =INDEX(Album!$D:$D, MATCH(B24,Album!$C:$C,0)) -> 2003 | D24: 10 | E24: Hearts of Servants
A25: =INDEX(Album!$A:$A, MATCH(B25,Album!$C:$C,0)) -> 2 | B25: Carry Away | C25: =INDEX(Album!$D:$D, MATCH(B25,Album!$C:$C,0)) -> 2003 | D25: 11 | E25: The Blood
A26: =INDEX(Album!$A:$A, MATCH(B26,Album!$C:$C,0)) -> 2 | B26: Carry Away | C26: =INDEX(Album!$D:$D, MATCH(B26,Album!$C:$C,0)) -> 2003 | D26: 12 | E26: Water of the Word
A27: =INDEX(Album!$A:$A, MATCH(B27,Album!$C:$C,0)) -> 2 | B27: Carry Away | C27: =INDEX(Album!$D:$D, MATCH(B27,Album!$C:$C,0)) -> 2003 | D27: 13 | E27: Be Near | F27: Radio Version
A28: =INDEX(Album!$A:$A, MATCH(B28,Album!$C:$C,0)) -> 3 | B28: Clean | C28: =INDEX(Album!$D:$D, MATCH(B28,Album!$C:$C,0)) -> 2004 | D28: 1 | E28: Saved by Grace | H28: Shane Barnard
A29: =INDEX(Album!$A:$A, MATCH(B29,Album!$C:$C,0)) -> 3 | B29: Clean | C29: =INDEX(Album!$D:$D, MATCH(B29,Album!$C:$C,0)) -> 2004 | D29: 2 | E29: Fringes | H29: Barnard
A30: =INDEX(Album!$A:$A, MATCH(B30,Album!$C:$C,0)) -> 3 | B30: Clean | C30: =INDEX(Album!$D:$D, MATCH(B30,Album!$C:$C,0)) -> 2004 | D30: 3 | E30: He Is Exalted | H30: Twila Paris
A31: =INDEX(Album!$A:$A, MATCH(B31,Album!$C:$C,0)) -> 3 | B31: Clean | C31: =INDEX(Album!$D:$D, MATCH(B31,Album!$C:$C,0)) -> 2004 | D31: 4 | E31: Waging War | H31: Barnard
A32: =INDEX(Album!$A:$A, MATCH(B32,Album!$C:$C,0)) -> 3 | B32: Clean | C32: =INDEX(Album!$D:$D, MATCH(B32,Album!$C:$C,0)) -> 2004 | D32: 5 | E32: Make Believe Jesus | H32: Barnard
A33: =INDEX(Album!$A:$A, MATCH(B33,Album!$C:$C,0)) -> 3 | B33: Clean | C33: =INDEX(Album!$D:$D, MATCH(B33,Album!$C:$C,0)) -> 2004 | D33: 6 | E33: You and I | H33: Barnard, Shane Everett
A34: =INDEX(Album!$A:$A, MATCH(B34,Album!$C:$C,0)) -> 3 | B34: Clean | C34: =INDEX(Album!$D:$D, MATCH(B34,Album!$C:$C,0)) -> 2004 | D34: 7 | E34: Yearn | H34: Barnard
A35: =INDEX(Album!$A:$A, MATCH(B35,Album!$C:$C,0)) -> 3 | B35: Clean | C35: =INDEX(Album!$D:$D, MATCH(B35,Album!$C:$C,0)) -> 2004 | D35: 8 | E35: God Did | H35: Barnard
A36: =INDEX(Album!$A:$A, MATCH(B36,Album!$C:$C,0)) -> 3 | B36: Clean | C36: =INDEX(Album!$D:$D, MATCH(B36,Album!$C:$C,0)) -> 2004 | D36: 9 | E36: Acres of Hope | H36: Barnard, Robbie Seay
A37: =INDEX(Album!$A:$A, MATCH(B37,Album!$C:$C,0)) -> 3 | B37: Clean | C37: =INDEX(Album!$D:$D, MATCH(B37,Album!$C:$C,0)) -> 2004 | D37: 10 | E37: There Is None Like You
A38: =INDEX(Album!$A:$A, MATCH(B38,Album!$C:$C,0)) -> 3 | B38: Clean | C38: =INDEX(Album!$D:$D, MATCH(B38,Album!$C:$C,0)) -> 2004 | D38: 11 | E38: Your Grace Is Sufficient | H38: Martin Nystrom
A39: =INDEX(Album!$A:$A, MATCH(B39,Album!$C:$C,0)) -> 4 | B39: Upstairs | C39: =INDEX(Album!$D:$D, MATCH(B39,Album!$C:$C,0)) -> 2004 | D39: 1 | E39: Psalm 13
A40: =INDEX(Album!$A:$A, MATCH(B40,Album!$C:$C,0)) -> 4 | B40: Upstairs | C40: =INDEX(Album!$D:$D, MATCH(B40,Album!$C:$C,0)) -> 2004 | D40: 2 | E40: Holy
...
