Workbook

Sheet Statistics
A1: Category | B1: Count | D1: Volume | E1: Category | F1: Count
A2: TWI Total | B2: 232 | D2: Volume 1 | E2: Vol. 1-12 | F2: 124
A3: ALL CCWS | B3: 186 | E3: Hymns | F3: 20
A4: ALL Other | B4: 163 | E4: Psalms | F4: 12
F5: =SUM(F2:F4) -> 156
A6: Category | B6: Count
A7: Vol. 1-12 | B7: 124 | D7: Volume 2 | E7: Vol. 13-23 | F7: 98
A8: Vol. 13-23 | B8: 98 | E8: TWI Special | F8: 10
A9: TWI Special | B9: 10 | E9: WI Lite | F9: 10
A10: WI Lite | B10: 10 | E10: WI Singles | F10: 1
A11: WI Singles | B11: 1 | E11: Christmas | F11: 20
A12: Hymns | B12: 20 | E12: From CCWS Xmas | F12: 6
A13: Christmas | B13: 20 | F13: =SUM(F7:F12) -> 145
A14: Psalms | B14: 12
A15: From CCWS | B15: 94 | D15: Extra | E15: From CCWS | F15: 94
A16: From CCWS Xmas | B16: 6 | E16: Other | F16: 69
A17: Other | B17: 69 | F17: =SUM(F15:F16) -> 163
B18: =SUM(B7:B17) -> 464

Sheet Albums
A1: Number | B1: Year | C1: Title | D1: Tracks | E1: In List? | F1: Band | G1: Type | H1: Category | I1: Release Date | J1: Notes
B2: 2002 | C2: Psalms, Vol. 1 | D2: 13 | E2: =IF(COUNTIF(Songs!$C:$C,C2)>0,"","NO") -> NO | G2: Studio | H2: Psalms | I2: 37411 | J2: Not on TWI
B3: 2008 | C3: Glory in the Highest: A Christmas Record | D3: 10 | E3: =IF(COUNTIF(Songs!$C:$C,C3)>0,"","NO") -> NO | G3: Studio | H3: Christmas | I3: 39735 | J3: Not on TWI
B4: 2014 | C4: The Worship Initiative, Vol. 01 | D4: 10 | E4: =IF(COUNTIF(Songs!$C:$C,C4)>0,"","NO") | F4: TWI | G4: Studio | I4: 41765
B5: 2014 | C5: The Worship Initiative, Vol. 02 | D5: 10 | E5: =IF(COUNTIF(Songs!$C:$C,C5)>0,"","NO") | F5: TWI | G5: Studio | I5: 41786
B6: 2014 | C6: The Worship Initiative, Vol. 03 | D6: 10 | E6: =IF(COUNTIF(Songs!$C:$C,C6)>0,"","NO") | F6: TWI | G6: Studio | I6: 41807
B7: 2014 | C7: The Worship Initiative, Vol. 04 | D7: 10 | E7: =IF(COUNTIF(Songs!$C:$C,C7)>0,"","NO") | F7: TWI | G7: Studio | I7: 41828
B8: 2014 | C8: The Worship Initiative, Vol. 05 | D8: 10 | E8: =IF(COUNTIF(Songs!$C:$C,C8)>0,"","NO") | F8: TWI | G8: Studio | I8: 41849
B9: 2014 | C9: The Worship Initiative, Vol. 06 | D9: 10 | E9: =IF(COUNTIF(Songs!$C:$C,C9)>0,"","NO") | F9: TWI | G9: Studio | I9: 41872
B10: 2014 | C10: The Worship Initiative, Vol. 07 | D10: 10 | E10: =IF(COUNTIF(Songs!$C:$C,C10)>0,"","NO") | F10: TWI | G10: Studio | I10: 41891
B11: 2014 | C11: The Worship Initiative, Vol. 08 | D11: 10 | E11: =IF(COUNTIF(Songs!$C:$C,C11)>0,"","NO") | F11: TWI | G11: Studio | I11: 41912
B12: 2014 | C12: The Worship Initiative, Vol. 09 | D12: 10 | E12: =IF(COUNTIF(Songs!$C:$C,C12)>0,"","NO") | F12: TWI | G12: Studio | I12: 41933
B13: 2014 | C13: The Worship Initiative, Vol. 10 | D13: 10 | E13: =IF(COUNTIF(Songs!$C:$C,C13)>0,"","NO") | F13: TWI | G13: Studio | I13: 41961
B14: 2015 | C14: Psalms, Vol. 2 | D14: 12 | E14: =IF(COUNTIF(Songs!$C:$C,C14)>0,"","NO") | G14: Studio | H14: Psalms | I14: 42300
B15: 2015 | C15: The Worship Initiative | D15: 10 | E15: =IF(COUNTIF(Songs!$C:$C,C15)>0,"","NO") | F15: TWI | G15: Studio | I15: 42122 | J15: Kickstarter Project
B16: 2016 | C16: Psalms Live | D16: 13 | E16: =IF(COUNTIF(Songs!$C:$C,C16)>0,"","NO") -> NO | G16: Live | H16: Psalms | I16: 42698 | J16: Not on TWI
B17: 2016 | C17: The Worship Initiative, Vol. 11 | D17: 11 | E17: =IF(COUNTIF(Songs!$C:$C,C17)>0,"","NO") | F17: TWI | G17: Studio | I17: 42643
B18: 2017 | C18: The Worship Initiative Christmas, Vol. 1 | D18: 10 | E18: =IF(COUNTIF(Songs!$C:$C,C18)>0,"","NO") | G18: Studio | H18: Christmas | I18: 42839
B19: 2017 | C19: The Worship Initiative Christmas, Vol. 2 | D19: 10 | E19: =IF(COUNTIF(Songs!$C:$C,C19)>0,"","NO") | G19: Studio | H19: Christmas | I19: 42839
B20: 2017 | C20: The Worship Initiative, Vol. 12 | D20: 13 | E20: =IF(COUNTIF(Songs!$C:$C,C20)>0,"","NO") | F20: TWI | G20: Studio | I20: 42839
B21: 2017 | C21: The Worship Initiative, Vol. 13 | D21: 5 | E21: =IF(COUNTIF(Songs!$C:$C,C21)>0,"","NO") | F21: TWI | G21: Studio | I21: 43000
B22: 2017 | C22: The Worship Initiative, Vol. 14 | D22: 5 | E22: =IF(COUNTIF(Songs!$C:$C,C22)>0,"","NO") | F22: TWI | G22: Studio | I22: 43039
B23: 2018 | C23: Hymns, Vol. 1 | D23: 10 | E23: =IF(COUNTIF(Songs!$C:$C,C23)>0,"","NO") | G23: Studio | H23: Hymns | I23: 43350
B24: 2018 | C24: Hymns, Vol. 2 | D24: 10 | E24: =IF(COUNTIF(Songs!$C:$C,C24)>0,"","NO") | G24: Studio | H24: Hymns | I24: 43700
B25: 2018 | C25: The Worship Initiative, Vol. 15 | D25: 5 | E25: =IF(COUNTIF(Songs!$C:$C,C25)>0,"","NO") | F25: TWI | G25: Studio | I25: 43145
B26: 2018 | C26: The Worship Initiative, Vol. 16 | D26: 10 | E26: =IF(COUNTIF(Songs!$C:$C,C26)>0,"","NO") | F26: TWI | G26: Studio | I26: 43297
B27: 2019 | C27: Hymns (Live) | D27: 13 | E27: =IF(COUNTIF(Songs!$C:$C,C27)>0,"","NO") -> NO | G27: Live | H27: Hymns | I27: 43504 | J27: Lots of duplicates
B28: 2019 | C28: The Worship Initiative Christmas, Vol. 3 | D28: 5 | E28: =IF(COUNTIF(Songs!$C:$C,C28)>0,"","NO") | G28: Studio | H28: Christmas | I28: 43797 | J28: Mainly duplicates of Vol. 1
B29: 2019 | C29: The Worship Initiative, Vol. 17 | D29: 12 | E29: =IF(COUNTIF(Songs!$C:$C,C29)>0,"","NO") | F29: TWI | G29: Studio | I29: 43630
B30: 2020 | C30: The Worship Initiative, Vol. 18 | D30: 10 | E30: =IF(COUNTIF(Songs!$C:$C,C30)>0,"","NO") | F30: TWI | G30: Studio | I30: 43847
B31: 2020 | C31: The Worship Initiative, Vol. 19 | D31: 10 | E31: =IF(COUNTIF(Songs!$C:$C,C31)>0,"","NO") | F31: TWI | G31: Studio | I31: 43889
B32: 2020 | C32: The Worship Initiative, Vol. 20 | D32: 10 | E32: =IF(COUNTIF(Songs!$C:$C,C32)>0,"","NO") | F32: TWI | G32: Studio | I32: 43924
B33: 2020 | C33: The Worship Initiative, Vol. 21 | D33: 10 | E33: =IF(COUNTIF(Songs!$C:$C,C33)>0,"","NO") | F33: TWI | G33: Studio | I33: 44001
B34: 2020 | C34: The Worship Initiative, Vol. 22 | D34: 11 | E34: =IF(COUNTIF(Songs!$C:$C,C34)>0,"","NO") | F34: TWI | G34: Studio | I34: 44099
B35: 2021 | C35: The Worship Initiative, Vol. 23 | D35: 10 | E35: =IF(COUNTIF(Songs!$C:$C,C35)>0,"","NO") | F35: TWI | G35: Studio | I35: 44204 | J35: Prerelease
B36: 2100 | C36: WI Lite | D36: 10 | E36: =IF(COUNTIF(Songs!$C:$C,C36)>0,"","NO") | G36: Unreleased | H36: Unreleased | J36: Played live but not included on any album
B37: 2100 | C37: WI Singles | D37: 1 | E37: =IF(COUNTIF(Songs!$C:$C,C37)>0,"","NO") | G37: Unreleased | H37: Unreleased

Sheet Songs
A1: Number | B1: Year | C1: Album | D1: Track | E1: Title | F1: Alt Title | G1: Author | H1: Key | I1: Tempo | J1: CCLI# | K1: Notes | L1: Status | M1: CCWS? | N1: Author | O1: Key | P1: Original Key | Q1: Tempo (BPM) | R1: Time Signature | S1: CCLI Song # | T1: Publication Year | U1: Copyright Holder | V1: CCLI# Accurate
B2: 2014 | C2: The Worship Initiative, Vol. 01 | D2: 1 | E2: Oceans | G2: Hillsong | H2: G | I2: 130 | J2: 6428767 | L2: Done | M2: Yes | N2: Joel Houston, Matt Crocker | O2: D | P2: D | Q2: 60 | R2: 4/4 | S2: 6428767 | T2: 2012 | U2: Hillsong Music Publishing Australia | V2: =IF(J2=S2,"Yes","") -> Yes
B3: 2014 | C3: The Worship Initiative, Vol. 01 | D3: 2 | E3: This Is Amazing Grace | G3: Phil Wickham | H3: Bb | I3: 99 | J3: 6333821 | L3: Done | M3: Yes | N3: Jeremy Riddle, Josh Farro | O3: G | P3: Bb | Q3: 100 | R3: 4/4 | S3: 6333821 | T3: 2012 | U3: Phil Wickham Music | V3: =IF(J3=S3,"Yes","") -> Yes
B4: 2014 | C4: The Worship Initiative, Vol. 01 | D4: 3 | E4: All the Poor and Powerless | G4: All Sons & Daughters | H4: B | I4: 72 | J4: 5881130 | L4: Done | M4: Yes | N4: David Leonard, Leslie Jordan | O4: A | P4: A | Q4: 76 | R4: 4/4 | S4: 5881130 | T4: 2011 | U4: Integrity's Alleluia! Music | V4: =IF(J4=S4,"Yes","") -> Yes
B5: 2014 | C5: The Worship Initiative, Vol. 01 | D5: 4 | E5: Lord I Need You | G5: Matt Maher | H5: B | I5: 72 | J5: 5925687 | L5: Done | M5: Yes | N5: Christy Nockels, Daniel Carson | O5: B | P5: B | Q5: 74 | R5: 4/4 | S5: 5925687 | T5: 2011 | U5: sixsteps Music | V5: =IF(J5=S5,"Yes","") -> Yes
B6: 2014 | C6: The Worship Initiative, Vol. 01 | D6: 5 | E6: In Christ Alone | F6: Passion | G6: Passion | H6: E | I6: 64 | J6: 3350395 | L6: Done | M6: Yes | N6: Keith Getty, Stuart Townend | O6: D | P6: D | Q6: 60 | R6: 3/4 | S6: 3350395 | T6: 2001 | U6: Thankyou Music | V6: =IF(J6=S6,"Yes","") -> Yes
B7: 2014 | C7: The Worship Initiative, Vol. 01 | D7: 6 | E7: Beautiful Things | G7: Gungor | H7: D | I7: 78 | J7: 5665521 | L7: Done
B8: 2014 | C8: The Worship Initiative, Vol. 01 | D8: 7 | E8: Come Thou Fount | F8: Vol. 1 | G8: The Worship Initiative | H8: D | I8: 68 | J8: 7029505 | L8: Done
B9: 2014 | C9: The Worship Initiative, Vol. 01 | D9: 8 | E9: 10,000 Reasons | G9: Matt Redman | H9: G | I9: 70 | J9: 6016351 | L9: Done | M9: Yes | N9: Jonas Myrin, Matt Redman | O9: G | P9: G | Q9: 73 | R9: 4/4 | S9: 6016351 | T9: 2011 | U9: Atlas Mountain Songs | V9: =IF(J9=S9,"Yes","") -> Yes
B10: 2014 | C10: The Worship Initiative, Vol. 01 | D10: 9 | E10: Whom Shall I Fear | F10: God of Angel Armies | G10: Chris Tomlin | H10: C | I10: 74 | J10: 6440288 | L10: Done | M10: Yes | N10: Chris Tomlin, Ed Cash | O10: C | P10: C | Q10: 75 | R10: 4/4 | S10: 6440288 | T10: 2012 | U10: Alletrop Music | V10: =IF(J10=S10,"Yes","") -> Yes
B11: 2014 | C11: The Worship Initiative, Vol. 01 | D11: 10 | E11: Happy Day | G11: Tim Hughes | H11: C | I11: 132 | J11: 4847027 | L11: Done
B12: 2014 | C12: The Worship Initiative, Vol. 02 | D12: 1 | E12: Heart Starts Beating | G12: Tim Neufeld | H12: A | I12: 112 | J12: 6578772 | L12: N/A
B13: 2014 | C13: The Worship Initiative, Vol. 02 | D13: 2 | E13: Hosanna | F13: Praise is Rising | G13: Paul Baloche | H13: A | I13: 106 | J13: 4662491 | L13: Done | M13: Yes | N13: Brenton Brown, Paul Baloche | O13: G | P13: G | Q13: 114 | R13: 4/4 | S13: 4662491 | T13: 2006 | U13: Thankyou Music | V13: =IF(J13=S13,"Yes","") -> Yes
B14: 2014 | C14: The Worship Initiative, Vol. 02 | D14: 3 | E14: Forever Reign | G14: Hillsong | H14: C | I14: 83 | J14: 5639997 | L14: Done
B15: 2014 | C15: The Worship Initiative, Vol. 02 | D15: 4 | E15: Mercy | G15: Matt Redman | H15: C | I15: 73 | J15: 7000689 | L15: Done | M15: Yes | N15: Matt Redman, Jonas Myrin | O15: C | P15: C | Q15: 73 | R15: 4/4 | S15: 7000689 | T15: 2013 | U15: Atlas Mountain Songs | V15: =IF(J15=S15,"Yes","") -> Yes
B16: 2014 | C16: The Worship Initiative, Vol. 02 | D16: 5 | E16: How Great Is Our God | G16: Chris Tomlin | H16: C | I16: 84 | J16: 4348399 | L16: Done | M16: Yes | N16: Chris Tomlin, Ed Cash | O16: C | P16: C | Q16: 76 | R16: 4/4 | S16: 4348399 | T16: 2004 | U16: sixsteps Music | V16: =IF(J16=S16,"Yes","") -> Yes
B17: 2014 | C17: The Worship Initiative, Vol. 02 | D17: 6 | E17: You Are My All In All | G17: Dennis Jernigan | H17: G | I17: 128 | J17: 825356 | L17: Done | M17: Yes | N17: Dennis Jernigan | O17: F | P17: F | Q17: 80 | R17: 4/4 | S17: 825356 | T17: 1991 | U17: Shepherd's Heart Music, Inc. | V17: =IF(J17=S17,"Yes","") -> Yes
B18: 2014 | C18: The Worship Initiative, Vol. 02 | D18: 7 | E18: We Exalt Thee | G18: Pete Sanchez Jr. | H18: G | I18: 68 | J18: 17803 | L18: N/A
B19: 2014 | C19: The Worship Initiative, Vol. 02 | D19: 8 | E19: Our God | G19: Chris Tomlin | H19: B | I19: 106 | J19: 5677416 | L19: Done | M19: Yes | N19: Chris Tomlin, Jesse Reeves | O19: B | P19: B | Q19: 105 | R19: 4/4 | S19: 5677416 | T19: 2010 | U19: Atlas Mountain Songs | V19: =IF(J19=S19,"Yes","") -> Yes
B20: 2014 | C20: The Worship Initiative, Vol. 02 | D20: 9 | E20: Open the Eyes of My Heart | G20: Paul Baloche | H20: B | I20: 110 | J20: 2298355 | L20: Done | M20: Yes | N20: Paul Baloche | O20: E | P20: E | Q20: 112 | R20: 4/4 | S20: 2298355 | T20: 1997 | U20: Integrity's Hosanna! Music | V20: =IF(J20=S20,"Yes","") -> Yes
B21: 2014 | C21: The Worship Initiative, Vol. 02 | D21: 10 | E21: Better Is One Day | G21: Matt Redman | H21: E | I21: 79 | J21: 1097451 | L21: Done | M21: Yes | N21: Matt Redman | O21: E | P21: E | Q21: 77 | R21: 4/4 | S21: 1097451 | T21: 1995 | U21: Thankyou Music | V21: =IF(J21=S21,"Yes","") -> Yes
B22: 2014 | C22: The Worship Initiative, Vol. 03 | D22: 1 | E22: So I Can Love | G22: The Worship Initiative | H22: Ab | I22: 124 | J22: 7031125 | L22: N/A
B23: 2014 | C23: The Worship Initiative, Vol. 03 | D23: 2 | E23: I Will Follow | G23: Chris Tomlin | H23: G | I23: 96 | J23: 5806878 | L23: Done | M23: Yes | N23: Chris Tomlin, Jason Ingram | O23: A | P23: Bb | Q23: 96 | R23: 4/4 | S23: 5806878 | T23: 2010 | U23: SHOUT! Music Publishing Australia | V23: =IF(J23=S23,"Yes","") -> Yes
B24: 2014 | C24: The Worship Initiative, Vol. 03 | D24: 3 | E24: Liberty | G24: Shane & Shane | H24: G | I24: 111 | J24: 6186872 | L24: N/A
B25: 2014 | C25: The Worship Initiative, Vol. 03 | D25: 4 | E25: Oh Lord, You're Beautiful | G25: Keith Green | H25: G | I25: 56 | J25: 14514 | L25: Done
B26: 2014 | C26: The Worship Initiative, Vol. 03 | D26: 5 | E26: How He Loves | G26: John Mark McMillan | H26: C | I26: 72.5 | J26: 5032549 | L26: Done
B27: 2014 | C27: The Worship Initiative, Vol. 03 | D27: 6 | E27: Never Once | G27: Matt Redman | H27: C | I27: 70 | J27: 5997055 | L27: Done
B28: 2014 | C28: The Worship Initiative, Vol. 03 | D28: 7 | E28: Shout to the Lord | G28: Hillsong | H28: B | I28: 80 | J28: 1406918 | L28: Done | M28: Yes | N28: Darlene Zschech | O28: A | P28: A | Q28: 76 | R28: 4/4 | S28: 1406918 | T28: 1993 | U28: Wondrous Worship | V28: =IF(J28=S28,"Yes","") -> Yes
B29: 2014 | C29: The Worship Initiative, Vol. 03 | D29: 8 | E29: Before The Throne of God Above | G29: Shane & Shane | H29: Eb | I29: 68 | J29: 2306412 | L29: Done | M29: Yes | N29: Charitie L. Bancroft, Vikki Cook | O29: D | P29: D | Q29: 76 | R29: 3/4 | S29: 2306412 | T29: 1997 | U29: Sovereign Grace Worship | V29: =IF(J29=S29,"Yes","") -> Yes
B30: 2014 | C30: The Worship Initiative, Vol. 03 | D30: 9 | E30: Beautiful One | G30: Tim Hughes | H30: Eb | I30: 120 | J30: 3915912 | L30: Done | M30: Yes | N30: Tim Hughes | O30: D | P30: D | Q30: 122 | R30: 4/4 | S30: 3915912 | T30: 2002 | U30: Thankyou Music | V30: =IF(J30=S30,"Yes","") -> Yes
B31: 2014 | C31: The Worship Initiative, Vol. 03 | D31: 10 | E31: Blessed Be Your Name | G31: Matt Redman | H31: B | I31: 114 | J31: 3798438 | L31: Done | M31: Yes | N31: Beth Redman, Matt Redman | O31: B | P31: B | Q31: 116 | R31: 4/4 | S31: 3798438 | T31: 2002 | U31: Thankyou Music | V31: =IF(J31=S31,"Yes","") -> Yes
B32: 2014 | C32: The Worship Initiative, Vol. 04 | D32: 1 | E32: I Stand Amazed | F32: How Marvelous | G32: Chris Tomlin | H32: A | I32: 104 | J32: 7029507 | L32: Done
B33: 2014 | C33: The Worship Initiative, Vol. 04 | D33: 2 | E33: Our God Is Love | G33: Hillsong | H33: F# | I33: 118 | J33: 5636866 | L33: Done
B34: 2014 | C34: The Worship Initiative, Vol. 04 | D34: 3 | E34: Holy Is The Lord | G34: Chris Tomlin | H34: G | I34: 77 | J34: 4158039 | L34: Done
B35: 2014 | C35: The Worship Initiative, Vol. 04 | D35: 4 | E35: Here For You | G35: Matt Redman | H35: C | I35: 86 | J35: 5925649 | L35: Done
B36: 2014 | C36: The Worship Initiative, Vol. 04 | D36: 5 | E36: Always | G36: Passion | H36: C | I36: 72 | J36: 5881037 | L36: Done
B37: 2014 | C37: The Worship Initiative, Vol. 04 | D37: 6 | E37: Here I Am To Worship | G37: Tim Hughes | H37: C | I37: 69 | J37: 3266032 | L37: Done | M37: Yes | N37: Tim Hughes | O37: E | P37: E | Q37: 75 | R37: 4/4 | S37: 3266032 | T37: 2000 | U37: Thankyou Music | V37: =IF(J37=S37,"Yes","") -> Yes
B38: 2014 | C38: The Worship Initiative, Vol. 04 | D38: 7 | E38: Worthy of Affection | G38: Shane & Shane | H38: C | I38: 58 | J38: 5627772 | L38: NoNumber
B39: 2014 | C39: The Worship Initiative, Vol. 04 | D39: 8 | E39: Healer | G39: Hillsong | H39: A | I39: 77 | J39: 4873981 | L39: Done | M39: Yes | N39: Mike Guglielmucci | O39: B | P39: B | Q39: 80 | R39: 4/4 | S39: 4873981 | T39: 2007 | U39: Planetshakers Ministries Int. Inc. | V39: =IF(J39=S39,"Yes","") -> Yes
B40: 2014 | C40: The Worship Initiative, Vol. 04 | D40: 9 | E40: It Is Well | F40: Hymn | G40: The Worship Initiative | H40: Db | I40: 68 | J40: 7029513 | L40: Done
...
