Workbook

Sheet Albums
A1: # | B1: Year | C1: Title | D1: Tracks | E1: In List? | F1: Band | G1: Type | H1: Category | I1: Exclude | J1: Release Date | K1: AlbumArt | L1: Notes
B2: 1997 | C2: Our Soul's Desire | D2: 14 | E2: =IF(COUNTIF(Songs!$C:$C,C2)>0,"","NO") | G2: Live | K2: NO
B3: 1998 | C3: Live Worship from the 268 Generation | D3: 13 | E3: =IF(COUNTIF(Songs!$C:$C,C3)>0,"","NO") | G3: Live
B4: 1999 | C4: Better Is One Day | D4: 12 | E4: =IF(COUNTIF(Songs!$C:$C,C4)>0,"","NO") | G4: Live
B5: 2000 | C5: One Day Live | D5: 12 | E5: =IF(COUNTIF(Songs!$C:$C,C5)>0,"","NO") | G5: Live
B6: 2000 | C6: The Road to One Day | D6: 12 | E6: =IF(COUNTIF(Songs!$C:$C,C6)>0,"","NO") | G6: Studio
B7: 2002 | C7: Our Love is Loud | D7: 13 | E7: =IF(COUNTIF(Songs!$C:$C,C7)>0,"","NO") | G7: Live
B8: 2003 | C8: Sacred Revolution: Songs From OneDay 03 | D8: 13 | E8: =IF(COUNTIF(Songs!$C:$C,C8)>0,"","NO") | G8: Live
B9: 2004 | C9: Hymns Ancient and Modern | D9: 14 | E9: =IF(COUNTIF(Songs!$C:$C,C9)>0,"","NO") | G9: Live
B10: 2005 | C10: How Great Is Our God | D10: 13 | E10: =IF(COUNTIF(Songs!$C:$C,C10)>0,"","NO") | G10: Live
B11: 2005 | C11: Passion 05 | D11: 2 | E11: =IF(COUNTIF(Songs!$C:$C,C11)>0,"","NO") | G11: Compilation
B12: 2006 | C12: Everything Glorious | D12: 13 | E12: =IF(COUNTIF(Songs!$C:$C,C12)>0,"","NO") | G12: Live
B13: 2006 | C13: Passion: The Early Session | D13: 4 | E13: =IF(COUNTIF(Songs!$C:$C,C13)>0,"","NO") | G13: Compilation
B14: 2006 | C14: The Best of Passion (So Far) | D14: 30 | E14: =IF(COUNTIF(Songs!$C:$C,C14)>0,"","NO") -> NO | G14: Compilation | I14: Exclude
B15: 2007 | C15: Live From Passion07 | D15: 6 | E15: =IF(COUNTIF(Songs!$C:$C,C15)>0,"","NO") | G15: Compilation
B16: 2008 | C16: A Generation United for His Renown | D16: 14 | E16: =IF(COUNTIF(Songs!$C:$C,C16)>0,"","NO") | G16: Compilation
B17: 2008 | C17: God of This City | D17: 14 | E17: =IF(COUNTIF(Songs!$C:$C,C17)>0,"","NO") | G17: Live
B18: 2010 | C18: Passion: Awakening | D18: 12 | E18: =IF(COUNTIF(Songs!$C:$C,C18)>0,"","NO") | G18: Live
B19: 2011 | C19: Passion: Here for You | D19: 15 | E19: =IF(COUNTIF(Songs!$C:$C,C19)>0,"","NO") | G19: Live
B20: 2012 | C20: Passion: White Flag | D20: 17 | E20: =IF(COUNTIF(Songs!$C:$C,C20)>0,"","NO") | G20: Live
B21: 2013 | C21: Passion: Let the Future Begin | D21: 15 | E21: =IF(COUNTIF(Songs!$C:$C,C21)>0,"","NO") | G21: Live
B22: 2014 | C22: Passion: Take It All | D22: 14 | E22: =IF(COUNTIF(Songs!$C:$C,C22)>0,"","NO") | G22: Live
B23: 2014 | C23: Passion: The Essential Collection | D23: 15 | E23: =IF(COUNTIF(Songs!$C:$C,C23)>0,"","NO") -> NO | G23: Compilation | I23: Exclude
B24: 2015 | C24: Passion: Even So Come | D24: 16 | E24: =IF(COUNTIF(Songs!$C:$C,C24)>0,"","NO") | G24: Live
B25: 2016 | C25: Passion: Salvation's Tide Is Rising | D25: 10 | E25: =IF(COUNTIF(Songs!$C:$C,C25)>0,"","NO") | G25: Studio
B26: 2017 | C26: Glorioso Día | E26: =IF(COUNTIF(Songs!$C:$C,C26)>0,"","NO") -> NO | G26: Studio | I26: Exclude
B27: 2017 | C27: Worthy of Your Name | D27: 13 | E27: =IF(COUNTIF(Songs!$C:$C,C27)>0,"","NO") | G27: Live
B28: 2018 | C28: Whole Heart | D28: 11 | E28: =IF(COUNTIF(Songs!$C:$C,C28)>0,"","NO") | G28: Live
B29: 2019 | C29: Behold The Lamb | D29: 2 | E29: =IF(COUNTIF(Songs!$C:$C,C29)>0,"","NO") | G29: Live
B30: 2019 | C30: Follow You Anywhere | D30: 10 | E30: =IF(COUNTIF(Songs!$C:$C,C30)>0,"","NO") | G30: Live
B31: 2020 | C31: Hope Has A Name | D31: 7 | E31: =IF(COUNTIF(Songs!$C:$C,C31)>0,"","NO") | G31: Studio
B32: 2020 | C32: Passion Collection | D32: 58 | E32: =IF(COUNTIF(Songs!$C:$C,C32)>0,"","NO") -> NO | G32: Compilation | I32: Exclude
B33: 2020 | C33: Roar (Live from Passion 2020) | D33: 12 | E33: =IF(COUNTIF(Songs!$C:$C,C33)>0,"","NO") | G33: Live

Sheet Songs
A1: # | B1: Year | C1: Album | D1: Track | E1: Title | F1: Alt Title | G1: Author | H1: Key | I1: Tempo | J1: CCLI# | K1: Notes | L1: In MC?
B2: 1997 | C2: Our Soul's Desire | D2: 1 | E2: Glorify | J2: =INDEX([1]Songs!$L:$L,MATCH(E2,[1]Songs!$E:$E,0)) -> #N/A | L2: =IF(ISNUMBER(INDEX([1]Songs!$L:$L,MATCH(E2,[1]Songs!$E:$E,0))),"YES","")
B3: 1997 | C3: Our Soul's Desire | D3: 2 | E3: Sweet Wind | J3: =INDEX([1]Songs!$L:$L,MATCH(E3,[1]Songs!$E:$E,0)) -> #N/A | L3: =IF(ISNUMBER(INDEX([1]Songs!$L:$L,MATCH(E3,[1]Songs!$E:$E,0))),"YES","")
B4: 1997 | C4: Our Soul's Desire | D4: 3 | E4: As We Pray | J4: =INDEX([1]Songs!$L:$L,MATCH(E4,[1]Songs!$E:$E,0)) -> #N/A | L4: =IF(ISNUMBER(INDEX([1]Songs!$L:$L,MATCH(E4,[1]Songs!$E:$E,0))),"YES","")
B5: 1997 | C5: Our Soul's Desire | D5: 4 | E5: You Are Worthy of My Praise | J5: =INDEX([1]Songs!$L:$L,MATCH(E5,[1]Songs!$E:$E,0)) -> #N/A | L5: =IF(ISNUMBER(INDEX([1]Songs!$L:$L,MATCH(E5,[1]Songs!$E:$E,0))),"YES","")
B6: 1997 | C6: Our Soul's Desire | D6: 5 | E6: Lord Of The Heavens | J6: =INDEX([1]Songs!$L:$L,MATCH(E6,[1]Songs!$E:$E,0)) -> #N/A | L6: =IF(ISNUMBER(INDEX([1]Songs!$L:$L,MATCH(E6,[1]Songs!$E:$E,0))),"YES","")
B7: 1997 | C7: Our Soul's Desire | D7: 6 | E7: Break Our Hearts | J7: =INDEX([1]Songs!$L:$L,MATCH(E7,[1]Songs!$E:$E,0)) -> #N/A | L7: =IF(ISNUMBER(INDEX([1]Songs!$L:$L,MATCH(E7,[1]Songs!$E:$E,0))),"YES","")
B8: 1997 | C8: Our Soul's Desire | D8: 7 | E8: We Fall Down | J8: =INDEX([1]Songs!$L:$L,MATCH(E8,[1]Songs!$E:$E,0)) -> #N/A | L8: =IF(ISNUMBER(INDEX([1]Songs!$L:$L,MATCH(E8,[1]Songs!$E:$E,0))),"YES","")
B9: 1997 | C9: Our Soul's Desire | D9: 8 | E9: Mercy Rain | J9: =INDEX([1]Songs!$L:$L,MATCH(E9,[1]Songs!$E:$E,0)) -> #N/A | L9: =IF(ISNUMBER(INDEX([1]Songs!$L:$L,MATCH(E9,[1]Songs!$E:$E,0))),"YES","")
B10: 1997 | C10: Our Soul's Desire | D10: 9 | E10: Spirit Fall On Me | J10: =INDEX([1]Songs!$L:$L,MATCH(E10,[1]Songs!$E:$E,0)) -> #N/A | L10: =IF(ISNUMBER(INDEX([1]Songs!$L:$L,MATCH(E10,[1]Songs!$E:$E,0))),"YES","")
B11: 1997 | C11: Our Soul's Desire | D11: 10 | E11: You Alone | J11: =INDEX([1]Songs!$L:$L,MATCH(E11,[1]Songs!$E:$E,0)) -> #N/A | L11: =IF(ISNUMBER(INDEX([1]Songs!$L:$L,MATCH(E11,[1]Songs!$E:$E,0))),"YES","")
B12: 1997 | C12: Our Soul's Desire | D12: 11 | E12: Amazing Love | J12: =INDEX([1]Songs!$L:$L,MATCH(E12,[1]Songs!$E:$E,0)) -> #N/A | L12: =IF(ISNUMBER(INDEX([1]Songs!$L:$L,MATCH(E12,[1]Songs!$E:$E,0))),"YES","")
B13: 1997 | C13: Our Soul's Desire | D13: 12 | E13: O For A Thousand Tounges To Sing | J13: =INDEX([1]Songs!$L:$L,MATCH(E13,[1]Songs!$E:$E,0)) -> #N/A | L13: =IF(ISNUMBER(INDEX([1]Songs!$L:$L,MATCH(E13,[1]Songs!$E:$E,0))),"YES","")
... B52: 2000 | C52: One Day Live | D52: 12 | E52: America | J52: =INDEX([1]Songs!$L:$L,MATCH(E52,[1]Songs!$E:$E,0)) -> #N/A | L52: =IF(ISNUMBER(INDEX([1]Songs!$L:$L,MATCH(E52,[1]Songs!$E:$E,0))),"YES","")
B53: 2000 | C53: The Road to One Day | D53: 1 | E53: Salvation | G53: Charlie Hall | J53: =INDEX([1]Songs!$L:$L,MATCH(E53,[1]Songs!$E:$E,0)) -> #N/A | L53: =IF(ISNUMBER(INDEX([1]Songs!$L:$L,MATCH(E53,[1]Songs!$E:$E,0))),"YES","")
B54: 2000 | C54: The Road to One Day | D54: 2 | E54: Shout To The North | G54: Charlie Hall | J54: =INDEX([1]Songs!$L:$L,MATCH(E54,[1]Songs!$E:$E,0)) -> #N/A | L54: =IF(ISNUMBER(INDEX([1]Songs!$L:$L,MATCH(E54,[1]Songs!$E:$E,0))),"YES","")
B55: 2000 | C55: The Road to One Day | D55: 3 | E55: The Noise We Make | G55: Chris Tomlin | J55: =INDEX([1]Songs!$L:$L,MATCH(E55,[1]Songs!$E:$E,0)) -> #N/A | L55: =IF(ISNUMBER(INDEX([1]Songs!$L:$L,MATCH(E55,[1]Songs!$E:$E,0))),"YES","")
B56: 2000 | C56: The Road to One Day | D56: 4 | E56: Break Our Hearts | G56: Shelley Nirider | J56: =INDEX([1]Songs!$L:$L,MATCH(E56,[1]Songs!$E:$E,0)) -> #N/A | L56: =IF(ISNUMBER(INDEX([1]Songs!$L:$L,MATCH(E56,[1]Songs!$E:$E,0))),"YES","")
B57: 2000 | C57: The Road to One Day | D57: 5 | E57: Make A Joyful Noise / I Will Not Be Silent | G57: David Crowder | J57: =INDEX([1]Songs!$L:$L,MATCH(E57,[1]Songs!$E:$E,0)) -> #N/A | L57: =IF(ISNUMBER(INDEX([1]Songs!$L:$L,MATCH(E57,[1]Songs!$E:$E,0))),"YES","")
B58: 2000 | C58: The Road to One Day | D58: 6 | E58: Kindness | G58: Chris Tomlin | J58: =INDEX([1]Songs!$L:$L,MATCH(E58,[1]Songs!$E:$E,0)) -> #N/A | L58: =IF(ISNUMBER(INDEX([1]Songs!$L:$L,MATCH(E58,[1]Songs!$E:$E,0))),"YES","")
B59: 2000 | C59: The Road to One Day | D59: 7 | E59: Holy Visitation | G59: Charlie Hall | J59: =INDEX([1]Songs!$L:$L,MATCH(E59,[1]Songs!$E:$E,0)) -> #N/A | L59: =IF(ISNUMBER(INDEX([1]Songs!$L:$L,MATCH(E59,[1]Songs!$E:$E,0))),"YES","")
B60: 2000 | C60: The Road to One Day | D60: 8 | E60: We Are Hungry | G60: Steve Fee | J60: =INDEX([1]Songs!$L:$L,MATCH(E60,[1]Songs!$E:$E,0)) -> #N/A | L60: =IF(ISNUMBER(INDEX([1]Songs!$L:$L,MATCH(E60,[1]Songs!$E:$E,0))),"YES","")
B61: 2000 | C61: The Road to One Day | D61: 9 | E61: Prelude | J61: =INDEX([1]Songs!$L:$L,MATCH(E61,[1]Songs!$E:$E,0)) -> #N/A | L61: =IF(ISNUMBER(INDEX([1]Songs!$L:$L,MATCH(E61,[1]Songs!$E:$E,0))),"YES","")
B62: 2000 | C62: The Road to One Day | D62: 10 | E62: Holy Roar | G62: Christy Nockels | J62: =INDEX([1]Songs!$L:$L,MATCH(E62,[1]Songs!$E:$E,0)) -> #N/A | L62: =IF(ISNUMBER(INDEX([1]Songs!$L:$L,MATCH(E62,[1]Songs!$E:$E,0))),"YES","")
B63: 2000 | C63: The Road to One Day | D63: 11 | E63: Did You Feel The Mountains Tremble? | G63: Matt Redman | J63: =INDEX([1]Songs!$L:$L,MATCH(E63,[1]Songs!$E:$E,0)) -> #N/A | L63: =IF(ISNUMBER(INDEX([1]Songs!$L:$L,MATCH(E63,[1]Songs!$E:$E,0))),"YES","")
B64: 2000 | C64: The Road to One Day | D64: 12 | E64: Jesus, Lover Of My Soul | G64: Shelly Nirider | J64: =INDEX([1]Songs!$L:$L,MATCH(E64,[1]Songs!$E:$E,0)) -> #N/A | L64: =IF(ISNUMBER(INDEX([1]Songs!$L:$L,MATCH(E64,[1]Songs!$E:$E,0))),"YES","")
B65: 2002 | C65: Our Love is Loud | D65: 1 | E65: Here I Am To Worship | G65: Chris Tomlin | J65: =INDEX([1]Songs!$L:$L,MATCH(E65,[1]Songs!$E:$E,0)) -> 3266032 | L65: =IF(ISNUMBER(INDEX([1]Songs!$L:$L,MATCH(E65,[1]Songs!$E:$E,0))),"YES","") -> YES
B66: 2002 | C66: Our Love is Loud | D66: 2 | E66: Enough | G66: Chris Tomlin | J66: =INDEX([1]Songs!$L:$L,MATCH(E66,[1]Songs!$E:$E,0)) -> 3599479 | L66: =IF(ISNUMBER(INDEX([1]Songs!$L:$L,MATCH(E66,[1]Songs!$E:$E,0))),"YES","") -> YES
B67: 2002 | C67: Our Love is Loud | D67: 3 | E67: Famous One | G67: Chris Tomlin | J67: =INDEX([1]Songs!$L:$L,MATCH(E67,[1]Songs!$E:$E,0)) -> #N/A | L67: =IF(ISNUMBER(INDEX([1]Songs!$L:$L,MATCH(E67,[1]Songs!$E:$E,0))),"YES","")
B68: 2002 | C68: Our Love is Loud | D68: 4 | E68: Prepare The Way | G68: Charlie Hall | J68: =INDEX([1]Songs!$L:$L,MATCH(E68,[1]Songs!$E:$E,0)) -> #N/A | L68: =IF(ISNUMBER(INDEX([1]Songs!$L:$L,MATCH(E68,[1]Songs!$E:$E,0))),"YES","")
B69: 2002 | C69: Our Love is Loud | D69: 5 | E69: Sweep Me Away | G69: Charlie Hall | J69: =INDEX([1]Songs!$L:$L,MATCH(E69,[1]Songs!$E:$E,0)) -> #N/A | L69: =IF(ISNUMBER(INDEX([1]Songs!$L:$L,MATCH(E69,[1]Songs!$E:$E,0))),"YES","")
B70: 2002 | C70: Our Love is Loud | D70: 6 | E70: Madly | G70: Charlie Hall | J70: =INDEX([1]Songs!$L:$L,MATCH(E70,[1]Songs!$E:$E,0)) -> #N/A | L70: =IF(ISNUMBER(INDEX([1]Songs!$L:$L,MATCH(E70,[1]Songs!$E:$E,0))),"YES","")
B71: 2002 | C71: Our Love is Loud | D71: 7 | E71: Psalm 126 | G71: Charlie Hall | J71: =INDEX([1]Songs!$L:$L,MATCH(E71,[1]Songs!$E:$E,0)) -> #N/A | L71: =IF(ISNUMBER(INDEX([1]Songs!$L:$L,MATCH(E71,[1]Songs!$E:$E,0))),"YES","")
B72: 2002 | C72: Our Love is Loud | D72: 8 | E72: Wonderful King | G72: David Crowder Band | J72: =INDEX([1]Songs!$L:$L,MATCH(E72,[1]Songs!$E:$E,0)) -> #N/A | L72: =IF(ISNUMBER(INDEX([1]Songs!$L:$L,MATCH(E72,[1]Songs!$E:$E,0))),"YES","")
B73: 2002 | C73: Our Love is Loud | D73: 9 | E73: Our Love Is Loud | G73: David Crowder Band | J73: =INDEX([1]Songs!$L:$L,MATCH(E73,[1]Songs!$E:$E,0)) -> #N/A | L73: =IF(ISNUMBER(INDEX([1]Songs!$L:$L,MATCH(E73,[1]Songs!$E:$E,0))),"YES","")
... B77: 2002 | C77: Our Love is Loud | D77: 13 | E77: Dance In The River | G77: Chris Tomlin | J77: =INDEX([1]Songs!$L:$L,MATCH(E77,[1]Songs!$E:$E,0)) -> #N/A | L77: =IF(ISNUMBER(INDEX([1]Songs!$L:$L,MATCH(E77,[1]Songs!$E:$E,0))),"YES","")
B78: 2003 | C78: Sacred Revolution: Songs From OneDay 03 | D78: 1 | E78: O Praise Him | F78: All This for a King | J78: =INDEX([1]Songs!$L:$L,MATCH(E78,[1]Songs!$E:$E,0)) -> 4158022 | L78: =IF(ISNUMBER(INDEX([1]Songs!$L:$L,MATCH(E78,[1]Songs!$E:$E,0))),"YES","") -> YES
B79: 2003 | C79: Sacred Revolution: Songs From OneDay 03 | D79: 2 | E79: O Come Let Us Adore Him | J79: =INDEX([1]Songs!$L:$L,MATCH(E79,[1]Songs!$E:$E,0)) -> #N/A | L79: =IF(ISNUMBER(INDEX([1]Songs!$L:$L,MATCH(E79,[1]Songs!$E:$E,0))),"YES","")
B80: 2003 | C80: Sacred Revolution: Songs From OneDay 03 | D80: 3 | E80: Holy Is the Lord | J80: =INDEX([1]Songs!$L:$L,MATCH(E80,[1]Songs!$E:$E,0)) -> 4158039 | L80: =IF(ISNUMBER(INDEX([1]Songs!$L:$L,MATCH(E80,[1]Songs!$E:$E,0))),"YES","") -> YES
B81: 2003 | C81: Sacred Revolution: Songs From OneDay 03 | D81: 4 | E81: Come Let Us Return to the Lord | J81: =INDEX([1]Songs!$L:$L,MATCH(E81,[1]Songs!$E:$E,0)) -> #N/A | L81: =IF(ISNUMBER(INDEX([1]Songs!$L:$L,MATCH(E81,[1]Songs!$E:$E,0))),"YES","")
...

Sheet Rejected Compilations
A1: # | B1: Year | C1: Album | D1: Track | E1: Title | F1: Alt Title | G1: Author | H1: Key | I1: Tempo | J1: CCLI# | K1: Notes
B2: 2006 | C2: The Best of Passion (So Far) | D2: 1 | E2: Come And Listen | G2: David Crowder Band
B3: 2006 | C3: The Best of Passion (So Far) | D3: 2 | E3: You Alone | G3: Sam Perry
B4: 2006 | C4: The Best of Passion (So Far) | D4: 3 | E4: His Renown | G4: Christy Nockels
B5: 2006 | C5: The Best of Passion (So Far) | D5: 4 | E5: You're Worthy Of My Praise | G5: Charlie Hall
B6: 2006 | C6: The Best of Passion (So Far) | D6: 5 | E6: You Are My King | F6: Amazing Love | G6: Christy Nockels
B7: 2006 | C7: The Best of Passion (So Far) | D7: 6 | E7: Better Is One Day | G7: Charlie Hall
B8: 2006 | C8: The Best of Passion (So Far) | D8: 7 | E8: Did You Feel The Mountains Tremble? | G8: Matt Redman
B9: 2006 | C9: The Best of Passion (So Far) | D9: 8 | E9: Salvation | G9: Charlie Hall
B10: 2006 | C10: The Best of Passion (So Far) | D10: 9 | E10: Grace Flows Down | G10: Christy Nockels
B11: 2006 | C11: The Best of Passion (So Far) | D11: 10 | E11: We Fall Down | G11: Chris Tomlin
B12: 2006 | C12: The Best of Passion (So Far) | D12: 11 | E12: Our Love Is Loud | G12: David Crowder Band
B13: 2006 | C13: The Best of Passion (So Far) | D13: 12 | E13: Enough | G13: Chris Tomlin
B14: 2006 | C14: The Best of Passion (So Far) | D14: 13 | E14: Famous One | G14: Chris Tomlin
B15: 2006 | C15: The Best of Passion (So Far) | D15: 14 | E15: Blessed Be The Name | G15: Matt Redman
B16: 2006 | C16: The Best of Passion (So Far) | D16: 15 | E16: How Great Thou Art | G16: Charlie Hall
B17: 2006 | C17: The Best of Passion (So Far) | D17: 16 | E17: Holy Is The Lord | G17: Chris Tomlin
B18: 2006 | C18: The Best of Passion (So Far) | D18: 17 | E18: O Praise Him | F18: All This For A King | G18: David Crowder Band
B19: 2006 | C19: The Best of Passion (So Far) | D19: 18 | E19: Sing To The King | G19: Candi Pearson
B20: 2006 | C20: The Best of Passion (So Far) | D20: 19 | E20: Take My Life | F20: And Let It Be | G20: Chris Tomlin
B21: 2006 | C21: The Best of Passion (So Far) | D21: 20 | E21: No One Like You | G21: David Crowder Band
B22: 2006 | C22: The Best of Passion (So Far) | D22: 21 | E22: Marvelous Light | G22: Charlie Hall
B23: 2006 | C23: The Best of Passion (So Far) | D23: 22 | E23: How Great Is Our God | G23: Chris Tomlin
B24: 2006 | C24: The Best of Passion (So Far) | D24: 23 | E24: Here Is Our King | G24: David Crowder Band
B25: 2006 | C25: The Best of Passion (So Far) | D25: 24 | E25: Indescribable | G25: Chris Tomlin
B26: 2006 | C26: The Best of Passion (So Far) | D26: 25 | E26: All Over The World | G26: Matt Redman
B27: 2006 | C27: The Best of Passion (So Far) | D27: 26 | E27: You Never Let Go | G27: Matt Redman
B28: 2006 | C28: The Best of Passion (So Far) | D28: 27 | E28: Jesus Paid It All | G28: Kristian Stanfill
B29: 2006 | C29: The Best of Passion (So Far) | D29: 28 | E29: You Are My Joy | G29: David Crowder Band
B30: 2006 | C30: The Best of Passion (So Far) | D30: 29 | E30: Glorious | G30: Chris Tomlin
B31: 2006 | C31: The Best of Passion (So Far) | D31: 30 | E31: Jesus Lover Of My Soul | G31: Shelley Nirider
B32: 2014 | C32: Passion: The Essential Collection | D32: 1 | E32: Holy Is The Lord | G32: Chris Tomlin
B33: 2014 | C33: Passion: The Essential Collection | D33: 2 | E33: One Thing Remains | G33: Kristian Stanfill
B34: 2014 | C34: Passion: The Essential Collection | D34: 3 | E34: 10,000 Reasons | F34: Bless the Lord | G34: Matt Redman
B35: 2014 | C35: Passion: The Essential Collection | D35: 4 | E35: Our God | G35: Chris Tomlin
B36: 2014 | C36: Passion: The Essential Collection | D36: 5 | E36: How He Loves | G36: David Crowder Band
B37: 2014 | C37: Passion: The Essential Collection | D37: 6 | E37: Healing Is In Your Hands | G37: Christy Nockels
B38: 2014 | C38: Passion: The Essential Collection | D38: 7 | E38: Whom Shall I Fear | F38: God of Angels Armies | G38: Chris Tomlin
B39: 2014 | C39: Passion: The Essential Collection | D39: 8 | E39: You Never Let Me Go | G39: Matt Redman
B40: 2014 | C40: Passion: The Essential Collection | D40: 9 | E40: Amazing Grace | F40: My Chains Are Gone | G40: Chris Tomlin
...
